Workbook

Sheet Gráfico1

Sheet CONTROL DE RENTAS
AP1: T.C. | AQ1: 19.7567
N3: MODIFICAR | O3: MODIFICAR | P3: MODIFICAR | Q3: MODIFICAR | R3: MODIFICAR | S3: MODIFICAR | T3: MODIFICAR | U3: MODIFICAR | W3: MODIFICAR | X3: MODIFICAR | Y3: NO MOVER | Z3: NO MOVER | AA3: NO MOVER | AB3: NO MOVER | AC3: NO MOVER | AE3: NO MOVER | AG3: =Y3 -> NO MOVER | AH3: NO MOVER | AI3: NO MOVER | AJ3: NO MOVER | AK3: NO MOVER | AN3: NO MOVER | AO3: NO MOVER | AP3: NO MOVER | AQ3: NO MOVER | AS3: NO MOVER | AT3: MODIFICAR | AU3: MODIFICAR | AW3: MODIFICAR | BC3: MODIFICAR | BM3: CONTROL DE SEGURO POR EQUIPO | BT3: CONTROL DE SUBRENTA
A4: N.E. | B4: ENERO | C4: FEBRERO | D4: MARZO | E4: ABRIL | F4: MAYO | G4: JUNIO | H4: JULIO | I4: AGOSTO | J4: SEPTIEMBRE | K4: OCTUBRE | L4: NOVIEMBRE | M4: DICIEMBRE | N4: COMENTARIOS | O4: DENTRO O FUERA | P4: CONTRATO | Q4: CLIENTE | R4: COMPRADOR | S4: OBRA | T4: HORAS | U4: VENDEDOR | V4: SUMA | W4: FECHA INICIO DE PERIODO | X4: DIAS CONTRATADO | Y4: NUMERO DE EQUIPO | Z4: FECHA DE VENCIMIENTO | AA4: BALANCE POR FECHA | AB4: DIAS TRANSCURRIDOS | AC4: TIPO DE NEGOCIO | AD4: ASEGURADO | AE4: PROVEEDOR | AF4: 0 | AG4: NUMERO DE EQUIPO 2 | AH4: DESCRIPCION DEL EQUIPO | AI4: MARCA | AJ4: MODELO | AK4: NUMERO DE SERIE | AL4: CATEGORIA | AM4: CLASE | AN4: AÑO | AO4: PRECIO DE LISTA | AP4: PRECIO REAL AL CLIENTE | AQ4: COSTO PROVEEDOR (USD) | AR4: COSTO PROVEEDOR (MXN) | AS4: Ganancia | AT4: TIPO RENTA | AU4: INICIO DE RENTA | AV4: REGRESO DE EQUIPO | AW4: COMENTARIOS | AX4: CIUDAD | AY4: UBICACIÓN | AZ4: CONTACTO | BA4: TELEFONO | BB4: Columna3 | BC4: Columna4 | BD4: Columna5 | BE4: Columna6 | BF4: Columna7 | BG4: Columna8 | BH4: Columna9 | BI4: Columna10 | BJ4: Columna11 | BK4: Columna12 | BL4: Columna13 | BM4: Columna14 | BN4: Columna15 | BO4: Columna16 | BP4: Columna17 | BQ4: Columna18 | BR4: Columna19 | BS4: Columna20 | BT4: Columna21 | BU4: Columna22 | BV4: Columna23 | BW4: Columna24 | BX4: Columna25 | BY4: Columna26 | BZ4: DIAS | CA4: ESTATUS DE VENCIMIENTO
A5: 1 | B5: 2022-2105-2178 | F5: 2730 | I5: 3141 | J5: 3429 | K5: 3498-3607 | O5: DENTRO | P5: 5855 | Q5: MTP MANTENIMIENTO | R5: MTP MANTENIMIENTO | S5: SAISA | T5: 1922 | U5: CARLOS | V5: 1 | W5: 45957 | X5: 6 | Y5: 1 | Z5: =W5+X5 -> 45963 | AA5: =TODAY() -> 45957 | AB5: =AA5-W5 -> 0 | AC5: COMYMAQ | AD5: COMYMAQ | AE5: SEGAMAC | AF5: ELECTRICA | AG5: 1 | AH5: PLATAFORMA ARTICULADA ELECTRICA | AI5: GENIE | AJ5: Z33/18 | AK5: Z331816M-918 | AL5: 10 | AM5: 03 | AN5: 2016 | AT5: DIRECTA | AU5: 45929
A6: 2 | B6: 2022-2105-2178 | I6: 3205-3265 | J6: 3265-3432 | O6: DENTRO | P6: 5780 | Q6: ALEJANDRO RUBIO FLORES | R6: ALEJANDRO RUBIO FLORES | S6: PARQUE INDUSTRIAL ORADEL | T6: 530 | U6: CARLOS | V6: 1 | W6: 45927 | X6: 27 | Y6: 2 | Z6: =W6+X6 -> 45954 | AA6: =TODAY() -> 45957 | AB6: =AA6-W6 -> 30 | AC6: COMYMAQ | AD6: COMYMAQ | AE6: SEGAMAC | AF6: ELECTRICA | AG6: 2 | AH6: PLATAFORMA TIPO TIJERA | AI6: GENIE | AJ6: GS3246 | AK6: GS4616C - 17123 | AT6: DIRECTA | AU6: 45899
A7: 3 | E7: 2607 | F7: 2642 | H7: 2970-3032 | I7: 3126-3215-3252 | J7: 3311-3386-3427 | O7: DISPONIBLE | V7: 1 | Y7: 3 | Z7: =W7+X7 -> 0 | AA7: =TODAY() -> 45957 | AB7: =AA7-W7 -> 45957 | AC7: COMYMAQ | AD7: COMYMAQ | AE7: SEGAMAC | AF7: ELECTRICA | AG7: 3 | AH7: PLATAFORMA ARTICULADA ELECTRICA | AI7: GENIE | AJ7: Z33/18 | AK7: Z331816M-724 | AL7: 10 | AM7: 03 | AN7: 2016
A8: 4 | F8: 2726 | G8: 2779-2809 | J8: 3347-3429 | K8: 3498-3607 | O8: DENTRO | P8: 5856 | Q8: MTP MANTENIMIENTO | R8: MTP MANTENIMIENTO | S8: SAISA | T8: 1740 | U8: CARLOS | V8: 1 | W8: 45957 | X8: 6 | Y8: 4 | Z8: =W8+X8 -> 45963 | AA8: =TODAY() -> 45957 | AB8: =AA8-W8 -> 0 | AC8: COMYMAQ | AD8: COMYMAQ | AE8: SEGAMAC | AF8: ELECTRICA | AG8: 4 | AH8: PLATAFORMA ARTICULADA ELECTRICA | AI8: GENIE | AJ8: Z33/18 | AK8: Z331816M-776 | AL8: 10 | AM8: 03 | AN8: 2016 | AT8: DIRECTA | AU8: 45929
A9: 5 | E9: S/FACTURA | F9: 2635 | O9: DISPONIBLE | V9: 1 | Y9: 5 | Z9: =W9+X9 -> 0 | AA9: =TODAY() -> 45957 | AB9: =AA9-W9 -> 45957 | AC9: COMYMAQ | AD9: COMYMAQ | AE9: SEGAMAC | AF9: ELECTRICA | AG9: 5 | AH9: PLATAFORMA ARTICULADA ELECTRICA | AI9: GENIE | AJ9: Z33/18 | AK9: Z331816M-732 | AL9: 10 | AM9: 03 | AN9: 2016
A10: 6 | J10: 3313-3389 | K10: 3603 | O10: DENTRO | P10: 5923 | Q10: TROYA INDUSTRIAL MONTERREY | R10: TROYA INDUSTRIAL MONTERREY | S10: SANTA ROSA | T10: 1701 | U10: CARLOS | V10: 1 | W10: 45955 | X10: 1 | Y10: 6 | Z10: =W10+X10 -> 45956 | AA10: =TODAY() -> 45957 | AB10: =AA10-W10 -> 2 | AC10: COMYMAQ | AD10: COMYMAQ | AE10: SEGAMAC | AF10: ELECTRICA | AG10: 6 | AH10: PLATAFORMA ARTICULADA ELECTRICA | AI10: GENIE | AJ10: Z33/18 | AK10: Z331816M-627 | AL10: 10 | AM10: 03 | AN10: 2016 | AT10: DIRECTA | AU10: 45955
A11: 7 | E11: 2475-2526-2510 | F11: 2645 | G11: 2812 | K11: 3507-3508-3809 | O11: DENTRO | P11: 5400 | Q11: CRISA LIBBEY MEXICO | R11: CRISA LIBBEY MEXICO | S11: CRISA | T11: 1466 | U11: JORGE | V11: 1 | W11: 45960 | X11: 13 | Y11: 7 | Z11: =W11+X11 -> 45973 | AA11: =TODAY() -> 45957 | AB11: =AA11-W11 -> -3 | AC11: COMYMAQ | AD11: COMYMAQ | AE11: SEGAMAC | AF11: ELECTRICA | AG11: 7 | AH11: PLATAFORMA ARTICULADA ELECTRICA | AI11: GENIE | AJ11: Z33/18 | AK11: Z331816M-717 | AL11: 10 | AM11: 03 | AN11: 2016
A12: 8 | I12: 3109-3113 | J12: 3313-3389 | O12: DISPONIBLE | V12: 1 | Y12: 8 | Z12: =W12+X12 -> 0 | AA12: =TODAY() -> 45957 | AB12: =AA12-W12 -> 45957 | AC12: COMYMAQ | AD12: COMYMAQ | AE12: SEGAMAC | AF12: ELECTRICA | AG12: 8 | AH12: PLATAFORMA ARTICULADA ELECTRICA | AI12: GENIE | AJ12: Z33/18 | AK12: Z331816M-614 | AL12: 10 | AM12: 03 | AN12: 2016
A13: 9 | K13: 3602 | O13: DENTRO | P13: 5919 | Q13: TROYA INDUSTRIAL MONTERREY | R13: TROYA INDUSTRIAL MONTERREY | S13: SANTA ROSA | T13: 1402 | U13: CARLOS | V13: 1 | W13: 45954 | X13: 6 | Y13: 9 | Z13: =W13+X13 -> 45960 | AA13: =TODAY() -> 45957 | AB13: =AA13-W13 -> 3 | AC13: COMYMAQ | AD13: COMYMAQ | AE13: SEGAMAC | AF13: ELECTRICA | AG13: 9 | AH13: PLATAFORMA ARTICULADA ELECTRICA | AI13: GENIE | AJ13: Z33/18 | AK13: Z331816M-647 | AL13: 10 | AM13: 03 | AN13: 2016 | AT13: DIRECTA | AU13: 45954
A14: 10 | E14: 2583 | G14: 2805 | O14: DISPONIBLE | V14: 1 | Y14: 10 | Z14: =W14+X14 -> 0 | AA14: =TODAY() -> 45957 | AB14: =AA14-W14 -> 45957 | AC14: COMYMAQ | AD14: COMYMAQ | AE14: SEGAMAC | AF14: ELECTRICA | AG14: 10 | AH14: PLATAFORMA ARTICULADA ELECTRICA | AI14: GENIE | AJ14: Z33/18 | AK14: Z331816M-735 | AL14: 10 | AM14: 03 | AN14: 2016
A15: 11 | O15: DISPONIBLE | V15: 1 | Y15: 11 | Z15: =W15+X15 -> 0 | AA15: =TODAY() -> 45957 | AB15: =AA15-W15 -> 45957 | AC15: COMYMAQ | AD15: COMYMAQ | AE15: SEGAMAC | AF15: ELECTRICA | AG15: 11 | AH15: PLATAFORMA ARTICULADA ELECTRICA | AI15: GENIE | AJ15: Z33/18 | AK15: Z331816M-803 | AL15: 10 | AM15: 03 | AN15: 2016
A16: 12 | H16: 2933 | O16: DISPONIBLE | V16: 1 | Y16: 12 | Z16: =W16+X16 -> 0 | AA16: =TODAY() -> 45957 | AB16: =AA16-W16 -> 45957 | AC16: COMYMAQ | AD16: COMYMAQ | AE16: SEGAMAC | AF16: ELECTRICA | AG16: 12 | AH16: PLATAFORMA ARTICULADA ELECTRICA | AI16: GENIE | AJ16: Z33/18 | AK16: Z331816M-606 | AL16: 10 | AM16: 03 | AN16: 2016
A17: 13 | F17: 2744 | G17: 2811 | I17: 3205 | O17: DENTRO | P17: 5929 | Q17: ALLIANCE SPECIALIZED SYSTEMS | R17: MAYELA ORNELAS LOPEZ | S17: TERNIUM PESQUERIA | T17: 403 | U17: JORGE | V17: 1 | W17: 45957 | X17: 27 | Y17: 13 | Z17: =W17+X17 -> 45984 | AA17: =TODAY() -> 45957 | AB17: =AA17-W17 -> 0 | AC17: COMYMAQ | AD17: COMYMAQ | AE17: SEGAMAC | AF17: ELECTRICA | AG17: 13 | AH17: PLATAFORMA TIPO TIJERA | AI17: GENIE | AJ17: GS2632 | AK17: GS3216C-15829 | AL17: 10 | AM17: 03 | AN17: 2016 | AT17: DIRECTA | AU17: 45957
A18: 14 | O18: TALLER | V18: 1 | Y18: 14 | Z18: =W18+X18 -> 0 | AA18: =TODAY() -> 45957 | AB18: =AA18-W18 -> 45957 | AC18: COMYMAQ | AD18: COMYMAQ | AE18: SEGAMAC | AF18: ELECTRICA | AG18: 14 | AH18: PLATAFORMA TIPO TIJERA | AI18: GENIE | AJ18: GS2632 | AK18: GS3216C-16255 | AL18: 10 | AM18: 03 | AN18: 2016
A19: 15 | H19: 3047 | I19: 3230 | J19: 3376 | K19: 3548 | O19: DENTRO | P19: 5674 | Q19: JOSE MARIO RODRIGUEZ GUERRERO | R19: JOSE MARIO RODRIGUEZ GUERRERO | S19: NUEVO LAREDO | T19: 428 | U19: CARLOS | V19: 1 | W19: 45946 | X19: 27 | Y19: 15 | Z19: =W19+X19 -> 45973 | AA19: =TODAY() -> 45957 | AB19: =AA19-W19 -> 11 | AC19: COMYMAQ | AD19: COMYMAQ | AE19: SEGAMAC | AF19: ELECTRICA | AG19: 15 | AH19: PLATAFORMA TIPO TIJERA | AI19: GENIE | AJ19: GS2632 | AK19: GS3216C-15778 | AL19: 10 | AM19: 03 | AN19: 2016 | AT19: DIRECTA | AU19: 45864 | AX19: NUEVO LAREDO | AY19: https://maps.app.goo.gl/BLjB842ei3UivWf56
A20: 16 | I20: 3205 | K20: 3511 | O20: DENTRO | P20: 5892 | Q20: GRUAS Y ELEVADORES DE MAZATLAN | R20: PEDRO TORRES PEREZ | S20: WALMART REFORMA NUEVO LAREDO | T20: 699 | U20: OSCAR | V20: 1 | W20: 45946 | X20: 27 | Y20: 16 | Z20: =W20+X20 -> 45973 | AA20: =TODAY() -> 45957 | AB20: =AA20-W20 -> 11 | AC20: COMYMAQ | AD20: COMYMAQ | AE20: SEGAMAC | AF20: ELECTRICA | AG20: 16 | AH20: PLATAFORMA TIPO TIJERA | AI20: GENIE | AJ20: GS2632 | AK20: GS3216C-15592 | AL20: 10 | AM20: 03 | AN20: 2016 | AT20: DIRECTA | AU20: 45946
A21: 17 | G21: 2831 | H21: 2996 | I21: 3121 | J21: 3284 | K21: 3468-3503 | O21: DENTRO | P21: 5924 | Q21: DETEC DISTRIBUIDORA | R21: ALEJANDRO MARTINEZ | S21: PARQUE INDUSTRIAL ORADEL | T21: 30 | U21: OSCAR | V21: 1 | W21: 45957 | X21: 27 | Y21: 17 | Z21: =W21+X21 -> 45984 | AA21: =TODAY() -> 45957 | AB21: =AA21-W21 -> 0 | AC21: COMYMAQ | AD21: DINGLI | AE21: COMYMAQ | AF21: ELECTRICA | AG21: 17 | AH21: PLATAFORMA TIPO TIJERA | AI21: DINGLI | AJ21: JCPT1412AC | AK21: JPC024E03100 | AL21: 30 | AM21: 05 | AN21: 2024 | AT21: DIRECTA | AU21: 45955
A22: 18 | F22: 2613 | G22: 2824 | H22: 2856 | I22: 3172 | K22: 3527 | O22: DENTRO | P22: 5877 | Q22: ALLIANCE SPECIALIZED SYSTEMS | R22: MAYELA ORNELAS LOPEZ | S22: YANG FENG RAMOS ARIZPE | T22: 63 | U22: JORGE | V22: 1 | W22: 45940 | X22: 29 | Y22: 18 | Z22: =W22+X22 -> 45969 | AA22: =TODAY() -> 45957 | AB22: =AA22-W22 -> 17 | AC22: COMYMAQ | AD22: DINGLI | AE22: COMYMAQ | AF22: ELECTRICA | AG22: 18 | AH22: PLATAFORMA TIPO TIJERA | AI22: DINGLI | AJ22: JCPT1412AC | AK22: JPC024E03104 | AL22: 30 | AM22: 05 | AN22: 2024 | AT22: DIRECTA | AU22: 45940 | AX22: RAMOS ARIZPE | AY22: https://maps.app.goo.gl/L8aWSyrBaMKx3bP67?g_st=aw | AZ22: EDUARDO SANCHEZ | BA22: 8993183255
A23: 19 | E23: 2593 | F23: 2703 | G23: 2880 | H23: 3030 | I23: 3180 | J23: 3381 | O23: DENTRO | P23: 5556 | Q23: TENCO INTEGRACION DE SISTEMAS | R23: TENCO INTEGRACION DE SISTEMAS | S23: AMAZON | T23: 6 | U23: JORGE | V23: 1 | W23: 45940 | X23: 27 | Y23: 19 | Z23: =W23+X23 -> 45967 | AA23: =TODAY() -> 45957 | AB23: =AA23-W23 -> 17 | AC23: COMYMAQ | AD23: DINGLI | AE23: COMYMAQ | AF23: ELECTRICA | AG23: 19 | AH23: PLATAFORMA TIPO TIJERA | AI23: DINGLI | AJ23: JCPT1412AC | AK23: JPC024F03478 | AL23: 30 | AM23: 05 | AN23: 2024 | AT23: DIRECTA | AU23: 45800 | AX23: ZUA ZUA | AY23: https://goo.gl/maps/vWx22rAxy8Habx7EA?g_st=aw | AZ23: BEATRIZ MENDOZA | BA23: 55 7929 3205
A24: 20 | I24: 3128-3237 | J24: 3338 | K24: 3456 | O24: DENTRO | P24: 5814 | Q24: DETEC DISTRIBUIDORA | R24: ALEJANDRO MARTINEZ | S24: PARQUE INDUSTRIAL ORADEL | T24: 11 | U24: OSCAR | V24: 1 | W24: 45941 | X24: 27 | Y24: 20 | Z24: =W24+X24 -> 45968 | AA24: =TODAY() -> 45957 | AB24: =AA24-W24 -> 16 | AC24: COMYMAQ | AD24: DINGLI | AE24: COMYMAQ | AF24: ELECTRICA | AG24: 20 | AH24: PLATAFORMA TIPO TIJERA | AI24: DINGLI | AJ24: JCPT1412AC | AK24: JPC024F03480 | AL24: 30 | AM24: 05 | AN24: 2024 | AT24: DIRECTA | AU24: 45913 | AX24: NUEVO LAREDO | AY24: https://goo.gl/maps/vWx22rAxy8Habx7EA?g_st=aw | AZ24: ALEJANDRO | BA24: 55 5043 5386
A25: 21 | H25: 2925-2947-2984 | J25: 3328 | O25: DISPONIBLE | V25: 1 | Y25: 21 | Z25: =W25+X25 -> 0 | AA25: =TODAY() -> 45957 | AB25: =AA25-W25 -> 45957 | AC25: COMYMAQ | AD25: DINGLI | AE25: COMYMAQ | AF25: ELECTRICA | AG25: 21 | AH25: PLATAFORMA TIPO TIJERA | AI25: DINGLI | AJ25: JCPT1412AC | AK25: JPC024F03485 | AL25: 30 | AM25: 05 | AN25: 2024
A26: 22 | H26: 2946 | I26: 3103 | J26: 3391-3447 | K26: 3549 | O26: TALLER | V26: 1 | Y26: 22 | Z26: =W26+X26 -> 0 | AA26: =TODAY() -> 45957 | AB26: =AA26-W26 -> 45957 | AC26: COMYMAQ | AD26: DINGLI | AE26: COMYMAQ | AF26: ELECTRICA | AG26: 22 | AH26: PLATAFORMA TIPO TIJERA | AI26: DINGLI | AJ26: JCPT1412AC | AK26: JPC024F03476 | AL26: 30 | AM26: 05 | AN26: 2024
A27: 23 | H27: 2946 | I27: 3103 | J27: 3391-3447 | O27: DISPONIBLE | V27: 1 | Y27: 23 | Z27: =W27+X27 -> 0 | AA27: =TODAY() -> 45957 | AB27: =AA27-W27 -> 45957 | AC27: COMYMAQ | AD27: DINGLI | AE27: COMYMAQ | AF27: ELECTRICA | AG27: 23 | AH27: PLATAFORMA TIPO TIJERA | AI27: DINGLI | AJ27: JCPT1412AC | AK27: JPC024F03482 | AL27: 30 | AM27: 05 | AN27: 2024
A28: 24 | H28: 3021 | I28: 3158 | J28: 3392 | O28: DISPONIBLE | V28: 1 | Y28: 24 | Z28: =W28+X28 -> 0 | AA28: =TODAY() -> 45957 | AB28: =AA28-W28 -> 45957 | AC28: COMYMAQ | AD28: DINGLI | AE28: COMYMAQ | AF28: ELECTRICA | AG28: 24 | AH28: PLATAFORMA TIPO TIJERA | AI28: DINGLI | AJ28: JCPT1412AC | AK28: JPC024F03483 | AL28: 30 | AM28: 05 | AN28: 2024
A29: 25 | F29: 2760 | G29: 2760 | H29: 2971-3065 | I29: 3219 | J29: 3388 | K29: 3568 | O29: DENTRO | P29: 5683 | Q29: SOLUCIONES Y DESARROLLOS MEP | R29: ALEJANDRA NUÑEZ | S29: PARQUE INDUSTRIAL ORADEL | T29: 18 | U29: OSCAR | V29: 1 | W29: 45948 | X29: 27 | Y29: 25 | Z29: =W29+X29 -> 45975 | AA29: =TODAY() -> 45957 | AB29: =AA29-W29 -> 9 | AC29: COMYMAQ | AD29: DINGLI | AE29: COMYMAQ | AF29: ELECTRICA | AG29: 25 | AH29: PLATAFORMA TIPO TIJERA | AI29: DINGLI | AJ29: JCPT1412AC | AK29: JPC024A01020 | AL29: 30 | AM29: 05 | AN29: 2024 | AT29: DIRECTA | AU29: 45864 | AX29: NUEVO LAREDO | AY29: https://goo.gl/maps/vWx22rAxy8Habx7EA?g_st=aw
A30: 26 | H30: 3060 | I30: 3085-3249 | J30: 3275-3338 | K30: 3456 | O30: DENTRO | P30: 5813 | Q30: DETEC DISTRIBUIDORA | R30: ALEJANDRO MARTINEZ | S30: PARQUE INDUSTRIAL ORADEL | T30: 19 | U30: OSCAR | V30: 1 | W30: 45941 | X30: 27 | Y30: 26 | Z30: =W30+X30 -> 45968 | AA30: =TODAY() -> 45957 | AB30: =AA30-W30 -> 16 | AC30: COMYMAQ | AD30: DINGLI | AE30: COMYMAQ | AF30: ELECTRICA | AG30: 26 | AH30: PLATAFORMA TIPO TIJERA | AI30: DINGLI | AJ30: S1412AC+ | AK30: JPC024E00047 | AL30: 30 | AM30: 05 | AN30: 2024 | AT30: DIRECTA | AU30: 45913 | AX30: NUEVO LAREDO | AY30: https://goo.gl/maps/vWx22rAxy8Habx7EA?g_st=aw | AZ30: ALEJANDRO | BA30: 55 5043 5386
A31: 27 | B31: 2147 | G31: 2823 | H31: 3029 | I31: 3241 | O31: TALLER | V31: 1 | Y31: 27 | Z31: =W31+X31 -> 0 | AA31: =TODAY() -> 45957 | AB31: =AA31-W31 -> 45957 | AC31: COMYMAQ | AD31: COMYMAQ | AE31: COMYMAQ | AF31: COMBUSTIÓN | AG31: 27 | AH31: COMPRESOR | AI31: ATLAS COPCO | AJ31: XATS375T3 | AK31: 4500B1310CR072827 | AL31: 40 | AM31: 02
A32: 28 | D32: 2340 | E32: S/FACTURA | F32: 2747 | J32: 3325 | K32: 3455 | O32: DENTRO | P32: 5809 | Q32: DETEC DISTRIBUIDORA | R32: ALEJANDRO MARTINEZ | S32: PARQUE INDUSTRIAL ORADEL | T32: 8323 | U32: OSCAR | V32: 1 | W32: 45939 | X32: 27 | Y32: 28 | Z32: =W32+X32 -> 45966 | AA32: =TODAY() -> 45957 | AB32: =AA32-W32 -> 18 | AC32: COMYMAQ | AD32: COMYMAQ | AE32: COMYMAQ | AF32: COMBUSTIÓN | AG32: 28 | AH32: GENERADOR DE 100KVA | AI32: HIMOINSA | AJ32: HFW-100 T6 CEM7 VTA | AK32: 171005365 | AL32: 60 | AM32: 3 | AN32: 2017 | AT32: DIRECTA | AU32: 45912 | AX32: NUEVO LAREDO | AY32: https://goo.gl/maps/vWx22rAxy8Habx7EA?g_st=aw | AZ32: ALEJANDRO | BA32: 55 5043 5386
A33: 29 | C33: 2333 | E33: 2479 | F33: 2669 | G33: 2844 | H33: 3000 | I33: 3155 | J33: 3307 | K33: 3481 | O33: DENTRO | P33: 5609 | Q33: ELECTROTEKNIA DE MEXICO | R33: LIZ MEDEL | S33: FRACCIONAMIENTO INDUSTRIAL INTERPUERTO MONTERREY | T33: 6258 | U33: JORGE | V33: 1 | W33: 45937 | X33: 27 | Y33: 29 | Z33: =W33+X33 -> 45964 | AA33: =TODAY() -> 45957 | AB33: =AA33-W33 -> 20 | AC33: COMYMAQ | AD33: COMYMAQ | AE33: COMYMAQ | AF33: COMBUSTIÓN | AG33: 29 | AH33: GENERADOR DE 45KVA | AI33: HIMOINSA | AJ33: HYW-45T T6 CEM7 VTA | AK33: 201004069 | AL33: 60 | AM33: 02 | AN33: 2020 | AT33: DIRECTA | AU33: 45825 | AX33: SALINAS VICTORIA
A34: 30 | O34: TALLER | V34: 1 | Y34: 30 | Z34: =W34+X34 -> 0 | AA34: =TODAY() -> 45957 | AB34: =AA34-W34 -> 45957 | AC34: LO | AD34: SEGAMAC | AE34: SEGAMAC | AF34: ELECTRICA | AG34: 30 | AH34: PLATAFORMA ELECTRICA ARTICULADA | AI34: GENIE | AJ34: Z33/18 | AK34: Z331816M-631 | AL34: 10 | AM34: 06
A35: 31 | B35: 2001-2080 | C35: 2262 | D35: 2390 | E35: 2571 | G35: 2850-2851 | H35: 2999 | I35: 3173 | J35: 3331 | K35: 3510 | O35: DENTRO | P35: 5193 | Q35: ALLIANCE SPECIALIZED SYSTEMS | R35: MAYELA ORNELAS LOPEZ | S35: SAN LUIS | T35: 1416 | U35: JORGE | V35: 1 | W35: 45942 | X35: 29 | Y35: 31 | Z35: =W35+X35 -> 45971 | AA35: =TODAY() -> 45957 | AB35: =AA35-W35 -> 15 | AC35: LO | AD35: SEGAMAC | AE35: SEGAMAC | AF35: ELECTRICA | AG35: 31 | AH35: PLATAFORMA ELECTRICA ARTICULADA | AI35: GENIE | AJ35: Z33/18 | AK35: Z331816M-697 | AL35: 10 | AM35: 06 | AT35: DIRECTA | AU35: 45642 | AX35: SAN LUIS
A36: 32 | C36: S/FACTURA | D36: S/FACTURA | G36: 2900 | I36: 3193 | J36: S/FACTURA | K36: 3458-3495 | O36: DISPONIBLE | V36: 1 | Y36: 32 | Z36: =W36+X36 -> 0 | AA36: =TODAY() -> 45957 | AB36: =AA36-W36 -> 45957 | AC36: LO | AD36: SEGAMAC | AE36: SEGAMAC | AF36: COMBUSTIÓN | AG36: 32 | AH36: PLATAFORMA TIPO TIJERA | AI36: GENIE | AJ36: GS-5390 RT | AK36: GS9016F-51069 | AL36: 30 | AM36: 05
A37: 33 | O37: DISPONIBLE | V37: 1 | Y37: 33 | Z37: =W37+X37 -> 0 | AA37: =TODAY() -> 45957 | AB37: =AA37-W37 -> 45957 | AC37: LO | AD37: SEGAMAC | AE37: SEGAMAC | AF37: COMBUSTIÓN | AG37: 33 | AH37: PLATAFORMA TIPO TIJERA | AI37: GENIE | AJ37: GS-5390 RT | AK37: GS9016F-51110 | AL37: 30 | AM37: 05 | AN37: 2015
A38: 34 | B38: 2041-2042-2181 | C38: 2311 | E38: 2494 | F38: 2715-2742 | G38: 2892 | H38: 2982 | K38: 3483 | O38: DENTRO | P38: 5880 | Q38: VAGO INSTALACIONES | R38: VAGO INSTALACIONES | S38: KHOLER | T38: 175 | U38: JORGE | V38: 1 | W38: 45943 | X38: 27 | Y38: 34 | Z38: =W38+X38 -> 45970 | AA38: =TODAY() -> 45957 | AB38: =AA38-W38 -> 14 | AC38: COMYMAQ | AD38: COMYMAQ | AE38: COMYMAQ | AF38: ELECTRICA | AG38: 34 | AH38: PLATAFORMA TELESCOPICA ELECTRICA | AI38: ZOOMLION | AJ38: ZT22JE | AK38: 07771200100P000052 | AL38: 10 | AM38: 09 | AN38: 2024 | AT38: DIRECTA | AU38: 45943
A39: 35 | H39: 2998 | K39: 3646 | O39: DENTRO | P39: 5865 | Q39: PROYECTOS Y CONSTRUCCIONES SIERRA MADRE | R39: ALFONSO SANCHEZ | S39: DHL | T39: 45 | U39: JORGE | V39: 1 | W39: 45945 | X39: 27 | Y39: 35 | Z39: =W39+X39 -> 45972 | AA39: =TODAY() -> 45957 | AB39: =AA39-W39 -> 12 | AC39: COMYMAQ | AD39: COMYMAQ | AE39: COMYMAQ | AF39: ELECTRICA | AG39: 35 | AH39: PLATAFORMA TELESCOPICA ELECTRICA | AI39: ZOOMLION | AJ39: ZT22JE | AK39: 07712000100P000053 | AL39: 10 | AM39: 09 | AN39: 2024 | AT39: DIRECTA | AU39: 45945
A40: 36 | B40: S/FACTURA | C40: S/FACTURA | D40: 2375-2413-2437-2463 | E40: S/FACTURA | G40: 2797 | H40: 2993 | I40: 3143 | J40: 3289 | K40: 3450 | O40: DENTRO | P40: 5305 | Q40: INTERNATIONAL METAL BUILDING | R40: GERARDO GOMEZ LUNA | S40: GK STAMPING FRONTERA | T40: 195 | U40: JORGE | V40: 1 | W40: 45934 | X40: 29 | Y40: 36 | Z40: =W40+X40 -> 45963 | AA40: =TODAY() -> 45957 | AB40: =AA40-W40 -> 23 | AC40: COMYMAQ | AD40: COMYMAQ | AE40: COMYMAQ | AF40: COMBUSTIÓN | AG40: 36 | AH40: PLATAFORMA TELESCOPICA DE COMBUSTION | AI40: ZOOMLION | AJ40: ZT20J | AK40: 0771100001P000073 | AL40: 10 | AM40: 08 | AN40: 2024 | AT40: DIRECTA | AU40: 45784
A41: 37 | B41: 2064 | C41: 2186 | D41: 2367 | E41: 2582 | F41: 2699-2737 | G41: 2788 | H41: 2959-2995 | I41: 3089 | J41: 3359 | K41: 3530 | O41: DENTRO | P41: 5864 | Q41: PROYECTOS Y CONSTRUCCIONES SIERRA MADRE | R41: ALFFONSO SANCHEZ | S41: DHL | T41: 544 | U41: JORGE | V41: 1 | W41: 45934 | X41: 27 | Y41: 37 | Z41: =W41+X41 -> 45961 | AA41: =TODAY() -> 45957 | AB41: =AA41-W41 -> 23 | AC41: COMYMAQ | AD41: COMYMAQ | AE41: COMYMAQ | AF41: COMBUSTIÓN | AG41: 37 | AH41: PLATAFORMA TELESCOPICA DE COMBUSTION | AI41: ZOOMLION | AJ41: ZT20J | AK41: 0771100001P000074 | AL41: 10 | AM41: 08 | AN41: 2024 | AT41: DIRECTA | AU41: 45934 | AX41: CIENEGA DE FLORES | AY41: https://maps.app.goo.gl/ccrcNXeBW4d8daiJA | AZ41: LUIS ALANIS | BA41: 8123199902
...

Sheet REVISAR
C4: DENTRO O FUERA | D4: NUMERO DE CONTRATO | E4: NOMBRE DEL CLIENTE | F4: COMPRADOR | G4: OBRA | H4: HORAS | I4: VENDEDOR | K4: FECHA INICIO DE PERIODO | L4: DIAS CONTRATADO | M4: NUMERO DE EQUIPO | N4: VENCIMIENTO DE PERIODO | O4: BALANCE POR FECHA | P4: DIAS TRANSCURRIDOS | Q4: TIPO DE NEGOCIO | R4: ASEGURADO | S4: PROVEEDOR | T4: TOTAL | U4: =M4 -> NUMERO DE EQUIPO | V4: DESCRIPCION DEL EQUIPO | W4: MARCA | X4: MODELO | Y4: NUMERO DE SERIE | AB4: AÑO | AC4: PRECIO REAL | AD4: 0 | AE4: TIPO RENTA | AF4: INICIO RENTA | AG4: REGRESO DE EQUIPO | AH4: COMENTARIOS
C5: REGRESO | D5: 5363 | E5: HEMOECO | F5: DARA SANCHEZ | G5: EN SUS INSTALACIONES | I5: CARLOS | J5: 1 | K5: 45685 | L5: 27 | M5: 1 | N5: =K5+L5 -> 45712 | O5: =TODAY() -> 45957 | P5: =O5-K5 -> 272 | Q5: COMYMAQ | S5: COMYMAQ | U5: 1 | V5: ROMPEDORA | W5: CHICAGO PNEUMATICS | X5: CP1240 | AE5: DIRECTA | AF5: 45685 | AG5: 45708 | AI5: ORDEN N°54804, JORGE MONTOYA FUSION (CAMBIO POR FALLA EL DIA 15-02-20 EQUIPO #153) (CAMBIO POR FALLA EL DIA 31-03-23 EQUIPO #140) | AJ5: USD
A6: 11041 | C6: REGRESO | D6: 5263 | E6: HEMOECO | F6: ISAIAS VALDEZ | G6: EN SUS INSTALACIONES | I6: CARLOS | J6: 1 | K6: 45674 | L6: 27 | M6: 1 | N6: =K6+L6 -> 45701 | O6: =TODAY() -> 45957 | P6: =O6-K6 -> 283 | Q6: COMYMAQ | S6: COMYMAQ | U6: 1 | V6: ROMPEDORA | W6: CHICAGO PNEUMATICS | X6: CP1240 | AE6: DIRECTA | AF6: 45646 | AG6: 45680 | AI6: INTERCAMBIO POR EQUIPO #148 EL DIA 01-02-23
B7: 11217 | C7: REGRESO | D7: 5364 | E7: HEMOECO | F7: DARA SANCHEZ | G7: EN SUS INSTALACIONES | I7: CARLOS | J7: 1 | K7: 45685 | L7: 27 | M7: 2 | N7: =K7+L7 -> 45712 | O7: =TODAY() -> 45957 | P7: =O7-K7 -> 272 | Q7: COMYMAQ | S7: COMYMAQ | U7: 2 | V7: ROMPEDORA | W7: CHICAGO PNEUMATICS | X7: CP1240 | AE7: DIRECTA | AF7: 45685 | AG7: 45708 | AI7: INTERCAMBIO POR EQUIPO #238 EL DIA 20-02-23
C8: REGRESO | D8: 5264 | E8: HEMOECO | F8: ISAIAS VALDEZ | G8: EN SUS INSTALACIONES | I8: CARLOS | J8: 1 | K8: 45674 | L8: 27 | M8: 2 | N8: =K8+L8 -> 45701 | O8: =TODAY() -> 45957 | P8: =O8-K8 -> 283 | Q8: COMYMAQ | S8: COMYMAQ | U8: 2 | V8: ROMPEDORA | W8: CHICAGO PNEUMATICS | X8: CP1240 | AE8: DIRECTA | AF8: 45646 | AG8: 45680
A9: 9494-9540 | B9: 9686 | C9: REGRESO | D9: 5344 | E9: ANGEL RAMOS DE LEON | F9: ANGEL RAMOS DE LEON | G9: TERNIUM PESQUERIA | H9: 425 | I9: CARLOS | J9: 1 | K9: 45703 | L9: 3 | M9: 27 | N9: =K9+L9 -> 45706 | O9: =TODAY() -> 45957 | P9: =O9-K9 -> 254 | Q9: COMYMAQ | R9: COMYMAQ | S9: COMYMAQ | T9: COMBUSTIÓN | U9: 27 | V9: COMPRESOR | W9: ATLAS COPCO | X9: XATS375T3 | Y9: 4500B1310CR072827 | Z9: 40 | AA9: 02 | AE9: DIRECTA | AF9: 45675 | AG9: 45707 | AI9: USD
C10: REGRESO | D10: 4857 | E10: ZINK POWER | F10: RENE LARA | G10: ZINK POWER | H10: 4279 | I10: CARLOS | J10: 1 | K10: 45713 | L10: 27 | M10: 27 | N10: 45740 | O10: 45726 | P10: 13 | Q10: COMYMAQ | R10: COMYMAQ | S10: COMYMAQ | T10: COMBUSTIÓN | U10: 27 | V10: COMPRESOR | W10: ATLAS COPCO | X10: XATS375T3 | Y10: 4500B1310CR072827 | Z10: 40 | AA10: 02 | AE10: DIRECTA | AF10: 45405 | AG10: 45724 | AH10: INTERCAMBIO DE EQUIPO # 27 POR EL # 52
C11: REGRESO | D11: 5411 | E11: ALIMENTOS SR NATURAL | F11: DOMINGO AGUILAR HERNANDEZ | G11: ESCOBEDO | H11: 8128 | I11: JORGE | J11: 1 | K11: 45720 | L11: 6 | M11: 28 | N11: 45726 | O11: 45724 | P11: 4 | Q11: COMYMAQ | R11: COMYMAQ | S11: COMYMAQ | T11: COMBUSTIÓN | U11: 28 | V11: GENERADOR DE 100KVA | W11: HIMOINSA | X11: HFW-100 T6 CEM7 VTA | Y11: 171005365 | Z11: 60 | AA11: 3 | AB11: 2017 | AE11: DIRECTA | AF11: 45720 | AG11: 45723 | AI11: INTERCAMBIO POR EQUIPO #209 EL DIA 24-04-23
C12: REGRESO | D12: 5368 | E12: ALLIANCE SPECIALIZED SYSTEMS | F12: MAYELA ORNELAS LOPEZ | G12: MERCADO LIBRE | H12: 16 | I12: JORGE | J12: 1 | K12: 45687 | L12: 6 | M12: 34 | N12: =K12+L12 -> 45693 | O12: =TODAY() -> 45957 | P12: =O12-K12 -> 270 | Q12: COMYMAQ | R12: COMYMAQ | S12: COMYMAQ | T12: ELECTRICA | U12: 34 | V12: PLATAFORMA TELESCOPICA ELECTRICA | W12: ZOOMLION | X12: ZT22JE | Y12: 07771200100P000052 | Z12: 10 | AA12: 09 | AB12: 2024 | AE12: DIRECTA | AF12: 45687 | AG12: 45692
B13: 10303 | C13: REGRESO | D13: 5293 | E13: ARENKO | F13: ALEJANDRO | I13: CARLOS | J13: 1 | K13: 45667 | L13: 6 | M13: 34 | N13: =K13+L13 -> 45673 | O13: =TODAY() -> 45957 | P13: =O13-K13 -> 290 | Q13: COMYMAQ | R13: COMYMAQ | S13: COMYMAQ | T13: ELECTRICA | U13: 34 | V13: PLATAFORMA TELESCOPICA ELECTRICA | W13: ZOOMLION | X13: ZT22JE | Y13: 07771200100P000052 | Z13: 10 | AA13: 09 | AB13: 2024 | AE13: DIRECTA | AF13: 45660 | AG13: 45673 | AI13: USD
A14: 10240 | B14: 10436 | C14: REGRESO | D14: 5348 | E14: T3RC3TO CONSTRUCCIONES | F14: OSVALDO SANCHEZ | G14: PARQUE INDUSTRIAL MARTEL SAN JAVIER | H14: 22 | I14: JORGE | J14: 1 | K14: 45708 | L14: 13 | M14: 36 | N14: =K14+L14 -> 45721 | O14: =TODAY() -> 45957 | P14: =O14-K14 -> 249 | Q14: COMYMAQ | R14: COMYMAQ | S14: COMYMAQ | T14: COMBUSTIÓN | U14: 36 | V14: PLATAFORMA TELESCOPICA DE COMBUSTION | W14: ZOOMLION | X14: ZT20J | Y14: 0771100001P000073 | Z14: 10 | AA14: 08 | AB14: 2024 | AE14: DIRECTA | AF14: 45678 | AG14: 45722
A15: 10181 | B15: 10435 | C15: REGRESO | D15: 5325 | E15: DIANA MODESTA | F15: DIANA MODESTA | G15: EN SUS INSTALACIONES | H15: 9 | I15: CARLOS | J15: 1 | K15: 45668 | L15: 6 | M15: 36 | N15: =K15+L15 -> 45674 | O15: =TODAY() -> 45957 | P15: =O15-K15 -> 289 | Q15: COMYMAQ | R15: COMYMAQ | S15: COMYMAQ | T15: COMBUSTIÓN | U15: 36 | V15: PLATAFORMA TELESCOPICA DE COMBUSTION | W15: ZOOMLION | X15: ZT20J | Y15: 0771100001P000073 | Z15: 10 | AA15: 08 | AB15: 2024 | AE15: DIRECTA | AF15: 45668 | AG15: 45675
A16: 9034 | B16: 9175 | C16: REGRESO | D16: 5158 | E16: REDISA | F16: ROCIO | G16: KRONOS | H16: 7076 | I16: CARLOS | J16: 1 | K16: 45622 | L16: 27 | M16: 40 | N16: =K16+L16 -> 45649 | O16: =TODAY() -> 45957 | P16: =O16-K16 -> 335 | Q16: COMYMAQ | R16: COMYMAQ | S16: COMYMAQ | T16: COMBUSTIÓN | U16: 40 | V16: GENERADOR DE 45KVA | W16: HIMOINSA | X16: HYW-45 T6 | Y16: 181002534 | Z16: 60 | AA16: 02 | AC16: 35000 | AD16: 0 | AE16: DIRECTA | AF16: 45594 | AG16: 45639
A17: 9180 | C17: REGRESO | D17: 5433 | E17: ALIMENTOS SR NATURAL | F17: DOMINGO JOSÉ AGUILAR | G17: SR NATURAL (GALLETAS) | H17: 9787 | I17: JORGE | J17: 1 | K17: 45730 | L17: 0 | M17: 41 | N17: =K17+L17 -> 45730 | O17: =TODAY() -> 45957 | P17: =O17-K17 -> 227 | Q17: COMYMAQ | R17: COMYMAQ | S17: COMYMAQ | T17: COMBUSTIÓN | U17: 41 | V17: GENERADOR DE 45KVA | W17: HIMOINSA | X17: HYW-45 T6 | Y17: 181002535 | Z17: 60 | AA17: 02 | AC17: 35000 | AD17: 0 | AE17: DIRECTA | AF17: 45730 | AG17: 45731
A18: 9480 | B18: 9594 | C18: REGRESO | D18: 5242 | E18: REDISA | F18: ANGELES | G18: VYNMSA SPACE B | H18: 9765 | I18: CARLOS | J18: 1 | K18: 45632 | L18: 27 | M18: 41 | N18: =K18+L18 -> 45659 | O18: =TODAY() -> 45957 | P18: =O18-K18 -> 325 | Q18: COMYMAQ | R18: COMYMAQ | S18: COMYMAQ | T18: COMBUSTIÓN | U18: 41 | V18: GENERADOR DE 45KVA | W18: HIMOINSA | X18: HYW-45 T6 | Y18: 181002535 | Z18: 60 | AA18: 02 | AC18: 35000 | AD18: 0 | AE18: DIRECTA | AF18: 45632 | AG18: 45660
A19: 9005-9013-9088 | B19: 9157 | C19: REGRESO | D19: 5334 | E19: ARENKO | F19: ALEJANDRO | G19: DLG EL CARMEN | H19: 2681 | I19: CARLOS | J19: 1 | K19: 45699 | L19: 27 | M19: 42 | N19: =K19+L19 -> 45726 | O19: =TODAY() -> 45957 | P19: =O19-K19 -> 258 | Q19: COMYMAQ | R19: COMYMAQ | S19: COMYMAQ | T19: COMBUSTIÓN | U19: 42 | V19: SOLDADORA | W19: SHINDAIWA | X19: DGW400DMS | Y19: W00255006843 | Z19: 70 | AA19: 01 | AC19: 24000 | AD19: 0 | AE19: DIRECTA | AF19: 45671 | AG19: 45724
A20: 10433 | B20: 10544 | C20: REGRESO | D20: 5294 | E20: ARENKO | F20: ALEJANDRO | G20: CONEKTA 3 | H20: 2472 | I20: CARLOS | J20: 1 | K20: 45294 | L20: 2 | M20: 42 | N20: =K20+L20 -> 45296 | O20: =TODAY() -> 45957 | P20: =O20-K20 -> 663 | Q20: COMYMAQ | R20: COMYMAQ | S20: COMYMAQ | T20: COMBUSTIÓN | U20: 42 | V20: SOLDADORA | W20: SHINDAIWA | X20: DGW400DMS | Y20: W00255006843 | Z20: 70 | AA20: 01 | AC20: 24000 | AD20: 0 | AE20: DIRECTA | AF20: 45660 | AG20: 45664
B21: 9645-9711 | C21: REGRESO | D21: 5182 | E21: ARENKO | F21: ARENKO | G21: TREDEC 12 | H21: 3031 | I21: CARLOS | J21: 1 | K21: 45663 | L21: 27 | M21: 43 | N21: =K21+L21 -> 45690 | O21: =TODAY() -> 45957 | P21: =O21-K21 -> 294 | Q21: COMYMAQ | R21: COMYMAQ | S21: COMYMAQ | T21: COMBUSTIÓN | U21: 43 | V21: SOLDADORA | W21: SHINDAIWA | X21: DGW400DMS | Y21: W00255006848 | Z21: 70 | AA21: 01 | AC21: 24000 | AD21: 0 | AE21: DIRECTA | AF21: 45607 | AG21: 45689
A22: 9153 | B22: 9291 | C22: REGRESO | D22: 5195 | E22: ARENKO | F22: ARENKO | G22: FINSA GPE NAVE EATON | H22: 384 | I22: CARLOS | J22: 1 | K22: 45699 | L22: 27 | M22: 44 | N22: =K22+L22 -> 45726 | O22: =TODAY() -> 45957 | P22: =O22-K22 -> 258 | Q22: COMYMAQ | R22: COMYMAQ | S22: COMYMAQ | T22: COMBUSTIÓN | U22: 44 | V22: SOLDADORA | W22: SHINDAIWA | X22: DGW400DMS | Y22: W00255006861 | Z22: 70 | AA22: 01 | AC22: 24000 | AD22: 0 | AE22: DIRECTA | AF22: 45615 | AG22: 45715
A23: 9645-9711 | C23: DENTRO | D23: 5183 | E23: ARENKO | F23: ARENKO | G23: CONEKTA | H23: 3274 | I23: CARLOS | J23: 1 | K23: 45607 | L23: 6 | M23: 44 | N23: =K23+L23 -> 45613 | O23: =TODAY() -> 45957 | P23: =O23-K23 -> 350 | Q23: COMYMAQ | R23: COMYMAQ | S23: COMYMAQ | T23: COMBUSTIÓN | U23: 44 | V23: SOLDADORA | W23: SHINDAIWA | X23: DGW400DMS | Y23: W00255006861 | Z23: 70 | AA23: 01 | AC23: 24000 | AD23: 0 | AE23: DIRECTA | AF23: 45607 | AG23: 45611
A24: 9002 | C24: REGRESO | D24: 5328 | E24: REDISA | F24: CRISTAL | G24: RMSG MARTEL | H24: 5378 | I24: CARLOS | J24: 1 | K24: 45698 | L24: 6 | M24: 45 | N24: 45704 | O24: 45705 | P24: 7 | Q24: COMYMAQ | R24: COMYMAQ | S24: COMYMAQ | T24: COMBUSTIÓN | U24: 45 | V24: TORRE DE ILUMINACION | W24: WAKER | X24: LTV-6L | Y24: WNCLTV01APUM02629 | Z24: 50 | AA24: 01 | AB24: 2012 | AD24: 0 | AE24: DIRECTA | AF24: 45670 | AG24: 45705
A25: 9241 | C25: TALLER | D25: 5268 | E25: SALTERRA | F25: YAZMIN VARGAS | G25: NEMAK, GARCIA | H25: 5301 | I25: CARLOS | J25: 1 | K25: 45647 | L25: 1 | M25: 45 | N25: 45648 | O25: 45653 | P25: 6 | Q25: COMYMAQ | R25: COMYMAQ | S25: COMYMAQ | T25: COMBUSTIÓN | U25: 45 | V25: TORRE DE ILUMINACION | W25: WAKER | X25: LTV-6L | Y25: WNCLTV01APUM02629 | Z25: 50 | AA25: 01 | AB25: 2012 | AD25: 0 | AE25: SUB RENTA | AF25: 45647 | AG25: 45652
A26: 9096 | C26: DENTRO | D26: 5186 | E26: REDISA | F26: ROCIO | G26: INBURSA SUCURSAL MONTERREY | H26: 5064 | I26: CARLOS | J26: 1 | K26: 45638 | L26: 13 | M26: 45 | N26: =K26+L26 -> 45651 | O26: =TODAY() -> 45957 | P26: =O26-K26 -> 319 | Q26: COMYMAQ | R26: COMYMAQ | S26: COMYMAQ | T26: COMBUSTIÓN | U26: 45 | V26: TORRE DE ILUMINACION | W26: WAKER | X26: LTV-6L | Y26: WNCLTV01APUM02629 | Z26: 50 | AA26: 01 | AB26: 2012 | AD26: 0 | AE26: DIRECTA | AF26: 45610 | AG26: 45645
A27: 9556 | B27: 9642 | C27: DENTRO | D27: 5163 | E27: REDISA | F27: ROCIO | G27: EN SUS INSTALACIONES | H27: 5010 | I27: CARLOS | J27: 1 | K27: 45596 | L27: 6 | M27: 45 | N27: =K27+L27 -> 45602 | O27: =TODAY() -> 45957 | P27: =O27-K27 -> 361 | Q27: COMYMAQ | R27: COMYMAQ | S27: COMYMAQ | T27: COMBUSTIÓN | U27: 45 | V27: TORRE DE ILUMINACION | W27: WAKER | X27: LTV-6L | Y27: WNCLTV01APUM02629 | Z27: 50 | AA27: 01 | AB27: 2012 | AD27: 0 | AE27: DIRECTA | AF27: 45596 | AG27: 45603
A28: 10154-10293 | C28: REGRESO | D28: 5132 | E28: DISTRIBUIDORA KARCEMEX | F28: ROLANDO CONTRERAS | G28: UNILEVER | H28: 5007 | I28: CARLOS | J28: 1 | K28: 45584 | L28: 6 | M28: 45 | N28: =K28+L28 -> 45590 | O28: =TODAY() -> 45957 | P28: =O28-K28 -> 373 | Q28: COMYMAQ | R28: COMYMAQ | S28: COMYMAQ | T28: COMBUSTIÓN | U28: 45 | V28: TORRE DE ILUMINACION | W28: WAKER | X28: LTV-6L | Y28: WNCLTV01APUM02629 | Z28: 50 | AA28: 01 | AB28: 2012 | AD28: 0 | AE28: DIRECTA | AF28: 45584 | AG28: 45596
B29: 9592 | C29: REGRESO | D29: 5208 | E29: GOIMSA GRUAS Y SERVICIOS | F29: GOIMSA GRUAS Y SERVICIOS | G29: REYNOSA TAMAULIPAS | H29: 3483 | I29: CARLOS | J29: 1 | K29: 45680 | L29: 27 | M29: 46 | N29: 45707 | O29: 45715 | P29: 35 | Q29: COMYMAQ | R29: COMYMAQ | S29: COMYMAQ | T29: COMBUSTIÓN | U29: 46 | V29: TORRE DE ILUMINACION | W29: WAKER | X29: LTV-6L | Y29: WNCLTV01EPUM02683 | Z29: 50 | AA29: 01 | AB29: 2012 | AC29: 12000 | AE29: DIRECTA | AF29: 45624 | AG29: 45714
A30: 9179-9215-9281 | C30: REGRESO | D30: 5137 | E30: REDISA | F30: CRISTAL | G30: DULCES NOMBRES | H30: 3408 | I30: CARLOS | J30: 1 | K30: 45600 | L30: 13 | M30: 46 | N30: =K30+L30 -> 45613 | O30: =TODAY() -> 45957 | P30: =O30-K30 -> 357 | Q30: COMYMAQ | R30: COMYMAQ | S30: COMYMAQ | T30: COMBUSTIÓN | U30: 46 | V30: TORRE DE ILUMINACION | W30: WAKER | X30: LTV-6L | Y30: WNCLTV01EPUM02683 | Z30: 50 | AA30: 01 | AB30: 2012 | AC30: 12000 | AE30: DIRECTA | AF30: 45586 | AG30: 45607
A31: 10242-10243 | C31: CANCELADO | D31: 5133 | E31: DISTRIBUIDORA KARCEMEX | F31: ROLANDO CONTRERAS | G31: UNILEVER | H31: 3407 | I31: CARLOS | J31: 1 | K31: 45584 | L31: 6 | M31: 46 | N31: =K31+L31 -> 45590 | O31: =TODAY() -> 45957 | P31: =O31-K31 -> 373 | Q31: COMYMAQ | R31: COMYMAQ | S31: COMYMAQ | T31: COMBUSTIÓN | U31: 46 | V31: TORRE DE ILUMINACION | W31: WAKER | X31: LTV-6L | Y31: WNCLTV01EPUM02683 | Z31: 50 | AA31: 01 | AB31: 2012 | AC31: 12000 | AE31: DIRECTA | AF31: 45584 | AH31: CLIENTE CANCELO CONTARTO | AJ31: USD
A32: 9002 | C32: REGRESO | D32: 5119 | E32: JULIO OVIEDO | F32: JULIO OVIEDO | G32: OBRA TRANSYS | H32: 2474 | I32: CARLOS | J32: 1 | K32: 45602 | L32: 27 | M32: 47 | N32: =K32+L32 -> 45629 | O32: =TODAY() -> 45957 | P32: =O32-K32 -> 355 | Q32: COMYMAQ | R32: COMYMAQ | S32: COMYMAQ | T32: COMBUSTIÓN | U32: 47 | V32: PLATAFORMA TIPO TIJERA | W32: GENIE | X32: GS-5390 RT | Y32: GS9015-50990 | Z32: 30 | AA32: 05 | AC32: 50000 | AD32: 0 | AE32: DIRECTA | AF32: 45574 | AG32: 45643
B33: 9645-9711 | C33: REGRESO | D33: 5359 | E33: JULIO OVIEDO | F33: JULIO OVIEDO | G33: BOTCAT | H33: 1652 | I33: CARLOS | J33: 1 | K33: 45712 | L33: 27 | M33: 48 | N33: =K33+L33 -> 45739 | O33: =TODAY() -> 45957 | P33: =O33-K33 -> 245 | Q33: COMYMAQ | R33: COMYMAQ | S33: COMYMAQ | T33: COMBUSTIÓN | U33: 48 | V33: PLATAFORMA TIPO TIJERA | W33: GENIE | X33: GS-4069 RT | Y33: GS6915-7668 | Z33: 30 | AA33: 04 | AB33: 2016 | AC33: 35000 | AD33: 0 | AE33: DIRECTA | AF33: 45712 | AG33: 45726 | AH33: INTERCAMBIO DE EQUIPO # 48 POR EL # 49
A34: 9485 | C34: TALLER | D34: 5098 | E34: OSCAR CABRERA | F34: OSCAR CABRERA | G34: NIFCO | H34: 1635 | I34: CARLOS | J34: 1 | K34: 45562 | L34: 6 | M34: 48 | N34: 45568 | O34: 45569 | P34: 7 | Q34: COMYMAQ | R34: COMYMAQ | S34: COMYMAQ | T34: COMBUSTIÓN | U34: 48 | V34: PLATAFORMA TIPO TIJERA | W34: GENIE | X34: GS-4069 RT | Y34: GS6915-7668 | Z34: 30 | AB34: 2016 | AD34: 0 | AE34: SUB RENTA | AF34: 45562
A35: 9158-9198 | C35: CANCELADO | D35: 5098 | E35: OSCAR CABRERA | F35: OSCAR CABRERA | G35: NIFCO | H35: 1645 | I35: CARLOS | J35: 1 | K35: 45569 | L35: 6 | M35: 48 | N35: =K35+L35 -> 45575 | O35: =TODAY() -> 45957 | P35: =O35-K35 -> 388 | Q35: COMYMAQ | R35: COMYMAQ | S35: COMYMAQ | T35: COMBUSTIÓN | U35: 48 | V35: PLATAFORMA TIPO TIJERA | W35: GENIE | X35: GS-4069 RT | Y35: GS6915-7668 | Z35: 30 | AA35: 04 | AB35: 2016 | AC35: 35000 | AD35: 0 | AE35: SUB RENTA | AF35: 45562 | AG35: 45573 | AI35: MXN
C36: REGRESO | D36: 5327 | E36: ASESORES Y CONSULTORES EN TECNOLOGIA | F36: ROMARIO CASTILLO GUAJARDO | G36: VYNMSA SANTA CATARINA INDUSTRIAL PARK II | H36: 2772 | I36: CARLOS | J36: 1 | K36: 45670 | L36: 27 | M36: 49 | N36: =K36+L36 -> 45697 | O36: =TODAY() -> 45957 | P36: =O36-K36 -> 287 | Q36: COMYMAQ | R36: COMYMAQ | S36: COMYMAQ | T36: COMBUSTIÓN | U36: 49 | V36: PLATAFORMA TIPO TIJERA | W36: GENIE | X36: GS-4069 RT | Y36: GS6916F-8982 | Z36: 30 | AA36: 04 | AB36: 2016 | AC36: 35000 | AD36: 0 | AE36: DIRECTA | AF36: 45670 | AG36: 45698
A37: 9153 | B37: 9291 | C37: TALLER | D37: 5039 | E37: HECTOR HUGO GARCIA ROMERO | F37: HECTOR HUGO GARCIA ROMERO | G37: PARQUE MILLENIUM | I37: JORGE | J37: 1 | K37: 45642 | L37: 6 | M37: 49 | N37: =K37+L37 -> 45648 | O37: =TODAY() -> 45957 | P37: =O37-K37 -> 315 | Q37: COMYMAQ | R37: COMYMAQ | S37: COMYMAQ | T37: COMBUSTIÓN | U37: 49 | V37: PLATAFORMA TIPO TIJERA | W37: GENIE | X37: GS-4069 RT | Y37: GS6916F-8982 | Z37: 30 | AA37: 04 | AB37: 2016 | AC37: 35000 | AD37: 0
A38: 9155 | B38: 9320 | C38: REGRESO | D38: 5397 | E38: ANDREA YAZMIN | F38: ANDREA YAZMIN | G38: TORREON | H38: 1199 | I38: JORGE | J38: 1 | K38: 45708 | L38: 27 | M38: 50 | N38: =K38+L38 -> 45735 | O38: =TODAY() -> 45957 | P38: =O38-K38 -> 249 | Q38: COMYMAQ | R38: COMYMAQ | S38: COMYMAQ | T38: COMBUSTIÓN | U38: 50 | V38: PLATAFORMA TIPO TIJERA | W38: GENIE | X38: GS-4390 RT | Y38: GS9016F-52358 | Z38: 30 | AA38: 04 | AB38: 2015 | AC38: 40000 | AD38: 0 | AE38: DIRECTA | AF38: 45708 | AG38: 45726 | AH38: INTERCAMBIO DE EQUIPO # 50 POR EL # 79
A39: 9009 | B39: 9154 | C39: REGRESO | D39: 5359 | E39: JULIO OVIEDO | F39: JULIO OVIEDO | G39: BOTCAT | H39: 1185 | I39: CARLOS | J39: 1 | K39: 45684 | L39: 27 | M39: 50 | N39: =K39+L39 -> 45711 | O39: =TODAY() -> 45957 | P39: =O39-K39 -> 273 | Q39: COMYMAQ | R39: COMYMAQ | S39: COMYMAQ | T39: COMBUSTIÓN | U39: 50 | V39: PLATAFORMA TIPO TIJERA | W39: GENIE | X39: GS-4390 RT | Y39: GS9016F-52358 | Z39: 30 | AA39: 04 | AB39: 2015 | AC39: 40000 | AD39: 0 | AE39: DIRECTA | AF39: 45684 | AG39: 45700
A40: 9931 | C40: REGRESO | D40: 5120 | E40: JULIO OVIEDO | F40: JULIO OVIEDO | G40: OBRA TRANSYS | H40: 1064 | I40: CARLOS | J40: 1 | K40: 45658 | L40: 27 | M40: 50 | N40: =K40+L40 -> 45685 | O40: =TODAY() -> 45957 | P40: =O40-K40 -> 299 | Q40: COMYMAQ | R40: COMYMAQ | S40: COMYMAQ | T40: COMBUSTIÓN | U40: 50 | V40: PLATAFORMA TIPO TIJERA | W40: GENIE | X40: GS-4390 RT | Y40: GS9016F-52358 | Z40: 30 | AA40: 04 | AB40: 2015 | AC40: 40000 | AD40: 0 | AE40: DIRECTA | AF40: 45574 | AG40: 45671 | AI40: USD
C41: DENTRO | D41: 5098 | E41: OSCAR CABRERA | F41: OSCAR CABRERA | G41: NIFCO | H41: 1064 | I41: CARLOS | J41: 1 | K41: 45562 | L41: 6 | M41: 50 | N41: =K41+L41 -> 45568 | O41: =TODAY() -> 45957 | P41: =O41-K41 -> 395 | Q41: COMYMAQ | R41: COMYMAQ | S41: COMYMAQ | T41: COMBUSTIÓN | U41: 50 | V41: PLATAFORMA TIPO TIJERA | W41: GENIE | X41: GS-4390 RT | Y41: GS9016F-52358 | Z41: 30
A42: 10239 | C42: REGRESO | D42: 5367 | E42: REDISA | F42: TADEO | G42: ANIDA | H42: 4887 | I42: CARLOS | J42: 1 | K42: 45694 | L42: 1 | M42: 51 | N42: =K42+L42 -> 45695 | O42: =TODAY() -> 45957 | P42: =O42-K42 -> 263 | Q42: COMYMAQ | R42: COMYMAQ | S42: COMYMAQ | T42: COMBUSTIÓN | U42: 51 | V42: COMPRESOR | W42: ATLAS COPCO | X42: XAS 375 | Y42: 8972 4224 87 | Z42: 40 | AA42: 02 | AC42: 51000 | AD42: 53040 | AE42: DIRECTA | AF42: 45687 | AG42: 45696 | AI42: USD
A43: 10009 | C43: REGRESO | D43: 4900 | E43: ZINK POWER | F43: RENE LARA | G43: ZINK POWER | H43: 4067 | I43: CARLOS | J43: 1 | K43: 45575 | L43: 27 | M43: 51 | N43: 45602 | O43: 45589 | P43: 14 | Q43: COMYMAQ | R43: COMYMAQ | S43: COMYMAQ | T43: COMBUSTIÓN | U43: 51 | V43: COMPRESOR | W43: ATLAS COPCO | X43: XAS 375 | Y43: 8972 4224 87 | Z43: 40 | AA43: 02 | AC43: 51000 | AD43: 53040 | AF43: 45435 | AG43: 45589
...

Sheet RENTABILIDAD GLOBAL
B2: =TODAY() -> 45957
B4: VENDEDOR | C4: EQUIPOS RENTADOS | D4: PORCENTAJE | E4: EQUIPOS COMPROMISO | F4: DIFERENCIA PARA META
B5: CARLOS | C5: =SUMIFS('CONTROL DE RENTAS'!V5:V307,'CONTROL DE RENTAS'!U5:U307,'RENTABILIDAD GLOBAL'!B5,'CONTROL DE RENTAS'!O5:O307,"DENTRO") -> 38 | D5: =C5/$C$15 -> 0.14615385 | E5: =+$C$15/5 -> 52 | F5: =C5-E5 -> -14
B6: JORGE | C6: =SUMIFS('CONTROL DE RENTAS'!V5:V307,'CONTROL DE RENTAS'!U5:U307,'RENTABILIDAD GLOBAL'!B6,'CONTROL DE RENTAS'!O5:O307,"DENTRO") -> 65 | D6: =C6/$C$15 -> 0.25 | E6: =+$C$15/5 -> 52 | F6: =C6-E6 -> 13
B7: JUAN | C7: =SUMIFS('CONTROL DE RENTAS'!V5:V307,'CONTROL DE RENTAS'!U5:U307,'RENTABILIDAD GLOBAL'!B7,'CONTROL DE RENTAS'!O5:O307,"DENTRO") -> 0 | D7: =C7/$C$15 -> 0 | E7: =+$C$15/5 -> 52 | F7: =C7-E7 -> -52
B8: OSCAR | C8: =SUMIFS('CONTROL DE RENTAS'!V4:V306,'CONTROL DE RENTAS'!U4:U306,'RENTABILIDAD GLOBAL'!B8,'CONTROL DE RENTAS'!O4:O306,"DENTRO") -> 32 | D8: =C8/$C$15 -> 0.12307692 | E8: =+$C$15/5 -> 52 | F8: =C8-E8 -> -20
B9: ARON | C9: =SUMIFS('CONTROL DE RENTAS'!V5:V307,'CONTROL DE RENTAS'!U5:U307,'RENTABILIDAD GLOBAL'!B9,'CONTROL DE RENTAS'!O5:O307,"DENTRO") -> 0 | D9: =C9/$C$15 -> 0 | E9: =+$C$15/5 -> 52 | F9: =C9-E9 -> -52
B11: TOTAL DE EQUIPOS RENTADOS | C11: =SUM(C5:C9) -> 135 | D11: =C11/$C$15 -> 0.51923077 | E11: =SUM(E5:E7) -> 156 | F11: =C11-E11 -> -21
B12: EQUIPOS DISPONIBLES | C12: {=SUM(SUMIFS('CONTROL DE RENTAS'!V2:V306,'CONTROL DE RENTAS'!O2:O306,$B$36:$B$37))} -> 75 | D12: =C12/$C$15 -> 0.28846154
B13: EQUIPOS EN TALLER EXTERNO | C13: =SUMIFS('CONTROL DE RENTAS'!V5:V307,'CONTROL DE RENTAS'!O5:O307,"TALLER EXTERNO") -> 1 | D13: =C13/$C$15 -> 0.0038461538
B14: EQUIPOS NO DISPONIBLES | C14: =SUM(SUMIFS('CONTROL DE RENTAS'!V5:V307,'CONTROL DE RENTAS'!O5:O307,"TALLER")) -> 49 | D14: =C14/$C$15 -> 0.18846154
B15: TOTAL DE EQUIPOS | C15: =SUM(C11:C14) -> 260 | D15: =C15/C15 -> 1
B17: EQUIPOS COMYMAQ | C17: =SUMIFS('CONTROL DE RENTAS'!V5:V307,'CONTROL DE RENTAS'!AC5:AC307,"COMYMAQ") -> 211 | D17: =C17/$C$15 -> 0.81153846
B18: EQUIPOS EN LEASING | C18: =SUMIFS('CONTROL DE RENTAS'!V5:V307,'CONTROL DE RENTAS'!AC5:AC307,"LO") -> 18 | D18: =C18/$C$15 -> 0.069230769
B19: EQUIPOS PROPIOS | C19: =C17+C18 -> 229 | D19: =D17+D18 -> 0.88076923
B20: EQUIPOS SUBARRENDADOS | C20: =SUMIFS('CONTROL DE RENTAS'!V5:V307,'CONTROL DE RENTAS'!AC5:AC307,"SUBARRENDADAS") -> 17 | D20: =C20/$C$15 -> 0.065384615
B21: EQUIPOS CONTRATO ESPECIAL | C21: =SUMIFS('CONTROL DE RENTAS'!V5:V307,'CONTROL DE RENTAS'!AC5:AC307,"CONTRATO ESPECIAL") -> 14 | D21: =C21/$C$15 -> 0.053846154
B22: TOTAL DE EQUIPOS | C22: =SUM(C19:C21) -> 260 | D22: =C22/C22 -> 1
B32: ESTATUS
B33: TALLER
B34: INTERCAMBIO
B35: TALLER EXTERNO
B36: DISPONIBLE
B37: INTERCAMBIO
N65: DENTRO | O65: 4502 | P65: GACSA | Q65: JOAO LEYVA | R65: EN SUS INSTALACIONES | S65: 376 | T65: APOLONIO | V65: 45169 | W65: 27
O97: 4501 | P97: ALLIANCE SPECIALIZED SYSTEMS | Q97: ROSEMBERG ALVARADO | R97: REYNOSA | S97: 2394 | T97: JORGE | V97: 45169 | W97: 29

Sheet RENTABILIDAD POR CATEGORIA
B2: =TODAY() -> 45957
B3: CATEGORIA | C3: CLASE | D3: DESCRIPCION | E3: CANTIDAD | F3: DENTRO | G3: DISPONIBLE | H3: TALLER | I3: GENERAL | J3: SEGMENTO RENTA | K3: SEGMENTO DISPONIBLE | L3: SEGMENTO TALLER | N3: SEGMENTO CLASE
B4: 10 | C4: PLATAFORMAS ARTICULADAS | J4: =SUM(F5:F14)/$E$41 -> 0.25668449
B5: 10 | C5: 01 | D5: 45 FT ELECTRICA CON JIB | E5: =SUMIFS('CONTROL DE RENTAS'!$V$42:$V$336,'CONTROL DE RENTAS'!$AL$42:$AL$336,$B5,'CONTROL DE RENTAS'!$AM$42:$AM$336,$C5) -> 18 | F5: =SUMIFS('CONTROL DE RENTAS'!$V$42:$V$336,'CONTROL DE RENTAS'!$AL$42:$AL$336,$B5,'CONTROL DE RENTAS'!$AM$42:$AM$336,$C5,'CONTROL DE RENTAS'!$O$42:$O$336,"DENTRO") -> 16 | G5: =SUMIFS('CONTROL DE RENTAS'!$V$42:$V$336,'CONTROL DE RENTAS'!$AL$42:$AL$336,$B5,'CONTROL DE RENTAS'!$AM$42:$AM$336,$C5,'CONTROL DE RENTAS'!$O$42:$O$336,"DISPONIBLE") -> 0 | H5: {=SUM(SUMIFS('CONTROL DE RENTAS'!$V$42:$V$336,'CONTROL DE RENTAS'!$AL$42:$AL$336,$B5,'CONTROL DE RENTAS'!$AM$42:$AM$336,$C5,'CONTROL DE RENTAS'!$O$42:$O$336,'RENTABILIDAD GLOBAL'!$B$33:$B$35))} -> 2 | I5: =$E5/$E$41 -> 0.096256684 | J5: =$F5/$E$41 -> 0.085561497 | K5: =$G5/$E$41 -> 0 | L5: =$H5/$E$41 -> 0.010695187 | N5: =+F5/E5 -> 0.88888889
B6: 10 | C6: 02 | D6: 45 FT COMBUSTION CON JIB | E6: =SUMIFS('CONTROL DE RENTAS'!$V$42:$V$336,'CONTROL DE RENTAS'!$AL$42:$AL$336,$B6,'CONTROL DE RENTAS'!$AM$42:$AM$336,$C6) -> 30 | F6: =SUMIFS('CONTROL DE RENTAS'!$V$42:$V$336,'CONTROL DE RENTAS'!$AL$42:$AL$336,$B6,'CONTROL DE RENTAS'!$AM$42:$AM$336,$C6,'CONTROL DE RENTAS'!$O$42:$O$336,"DENTRO") -> 18 | G6: =SUMIFS('CONTROL DE RENTAS'!$V$42:$V$336,'CONTROL DE RENTAS'!$AL$42:$AL$336,$B6,'CONTROL DE RENTAS'!$AM$42:$AM$336,$C6,'CONTROL DE RENTAS'!$O$42:$O$336,"DISPONIBLE") -> 3 | H6: {=SUM(SUMIFS('CONTROL DE RENTAS'!$V$42:$V$336,'CONTROL DE RENTAS'!$AL$42:$AL$336,$B6,'CONTROL DE RENTAS'!$AM$42:$AM$336,$C6,'CONTROL DE RENTAS'!$O$42:$O$336,'RENTABILIDAD GLOBAL'!$B$33:$B$35))} -> 9 | I6: =$E6/$E$41 -> 0.16042781 | J6: =$F6/$E$41 -> 0.096256684 | K6: =$G6/$E$41 -> 0.016042781 | L6: =$H6/$E$41 -> 0.048128342 | N6: =+F6/E6 -> 0.6
B7: 10 | C7: 03 | D7: 45 FT ELECTRICA SIN JIB | E7: =SUMIFS('CONTROL DE RENTAS'!$V$42:$V$336,'CONTROL DE RENTAS'!$AL$42:$AL$336,$B7,'CONTROL DE RENTAS'!$AM$42:$AM$336,$C7) -> 7 | F7: =SUMIFS('CONTROL DE RENTAS'!$V$42:$V$336,'CONTROL DE RENTAS'!$AL$42:$AL$336,$B7,'CONTROL DE RENTAS'!$AM$42:$AM$336,$C7,'CONTROL DE RENTAS'!$O$42:$O$336,"DENTRO") -> 5 | G7: =SUMIFS('CONTROL DE RENTAS'!$V$42:$V$336,'CONTROL DE RENTAS'!$AL$42:$AL$336,$B7,'CONTROL DE RENTAS'!$AM$42:$AM$336,$C7,'CONTROL DE RENTAS'!$O$42:$O$336,"DISPONIBLE") -> 1 | H7: {=SUM(SUMIFS('CONTROL DE RENTAS'!$V$42:$V$336,'CONTROL DE RENTAS'!$AL$42:$AL$336,$B7,'CONTROL DE RENTAS'!$AM$42:$AM$336,$C7,'CONTROL DE RENTAS'!$O$42:$O$336,'RENTABILIDAD GLOBAL'!$B$33:$B$35))} -> 1 | I7: =$E7/$E$41 -> 0.037433155 | J7: =$F7/$E$41 -> 0.026737968 | K7: =$G7/$E$41 -> 0.0053475936 | L7: =$H7/$E$41 -> 0.0053475936 | N7: =+F7/E7 -> 0.71428571
B8: 10 | C8: 04 | D8: 45 FT COMBUSTION SIN JIB | E8: =SUMIFS('CONTROL DE RENTAS'!$V$42:$V$336,'CONTROL DE RENTAS'!$AL$42:$AL$336,$B8,'CONTROL DE RENTAS'!$AM$42:$AM$336,$C8) -> 1 | F8: =SUMIFS('CONTROL DE RENTAS'!$V$42:$V$336,'CONTROL DE RENTAS'!$AL$42:$AL$336,$B8,'CONTROL DE RENTAS'!$AM$42:$AM$336,$C8,'CONTROL DE RENTAS'!$O$42:$O$336,"DENTRO") -> 1 | G8: =SUMIFS('CONTROL DE RENTAS'!$V$42:$V$336,'CONTROL DE RENTAS'!$AL$42:$AL$336,$B8,'CONTROL DE RENTAS'!$AM$42:$AM$336,$C8,'CONTROL DE RENTAS'!$O$42:$O$336,"DISPONIBLE") -> 0 | H8: {=SUM(SUMIFS('CONTROL DE RENTAS'!$V$42:$V$336,'CONTROL DE RENTAS'!$AL$42:$AL$336,$B8,'CONTROL DE RENTAS'!$AM$42:$AM$336,$C8,'CONTROL DE RENTAS'!$O$42:$O$336,'RENTABILIDAD GLOBAL'!$B$33:$B$35))} -> 0 | I8: =$E8/$E$41 -> 0.0053475936 | J8: =$F8/$E$41 -> 0.0053475936 | K8: =$G8/$E$41 -> 0 | L8: =$H8/$E$41 -> 0 | N8: =+F8/E8 -> 1
B9: 10 | C9: 05 | D9: 40 FT ELECTRICA NARROW | E9: =SUMIFS('CONTROL DE RENTAS'!$V$42:$V$336,'CONTROL DE RENTAS'!$AL$42:$AL$336,$B9,'CONTROL DE RENTAS'!$AM$42:$AM$336,$C9) -> 0 | F9: =SUMIFS('CONTROL DE RENTAS'!$V$42:$V$336,'CONTROL DE RENTAS'!$AL$42:$AL$336,$B9,'CONTROL DE RENTAS'!$AM$42:$AM$336,$C9,'CONTROL DE RENTAS'!$O$42:$O$336,"DENTRO") -> 0 | G9: =SUMIFS('CONTROL DE RENTAS'!$V$42:$V$336,'CONTROL DE RENTAS'!$AL$42:$AL$336,$B9,'CONTROL DE RENTAS'!$AM$42:$AM$336,$C9,'CONTROL DE RENTAS'!$O$42:$O$336,"DISPONIBLE") -> 0 | H9: {=SUM(SUMIFS('CONTROL DE RENTAS'!$V$42:$V$336,'CONTROL DE RENTAS'!$AL$42:$AL$336,$B9,'CONTROL DE RENTAS'!$AM$42:$AM$336,$C9,'CONTROL DE RENTAS'!$O$42:$O$336,'RENTABILIDAD GLOBAL'!$B$33:$B$35))} -> 0 | I9: =$E9/$E$41 -> 0 | J9: =$F9/$E$41 -> 0 | K9: =$G9/$E$41 -> 0 | L9: =$H9/$E$41 -> 0 | N9: 0
B10: 10 | C10: 06 | D10: 33 FT ELECTRICA | E10: =SUMIFS('CONTROL DE RENTAS'!$V$42:$V$336,'CONTROL DE RENTAS'!$AL$42:$AL$336,$B10,'CONTROL DE RENTAS'!$AM$42:$AM$336,$C10) -> 5 | F10: =SUMIFS('CONTROL DE RENTAS'!$V$42:$V$336,'CONTROL DE RENTAS'!$AL$42:$AL$336,$B10,'CONTROL DE RENTAS'!$AM$42:$AM$336,$C10,'CONTROL DE RENTAS'!$O$42:$O$336,"DENTRO") -> 0 | G10: =SUMIFS('CONTROL DE RENTAS'!$V$42:$V$336,'CONTROL DE RENTAS'!$AL$42:$AL$336,$B10,'CONTROL DE RENTAS'!$AM$42:$AM$336,$C10,'CONTROL DE RENTAS'!$O$42:$O$336,"DISPONIBLE") -> 4 | H10: {=SUM(SUMIFS('CONTROL DE RENTAS'!$V$42:$V$336,'CONTROL DE RENTAS'!$AL$42:$AL$336,$B10,'CONTROL DE RENTAS'!$AM$42:$AM$336,$C10,'CONTROL DE RENTAS'!$O$42:$O$336,'RENTABILIDAD GLOBAL'!$B$33:$B$35))} -> 1 | I10: =$E10/$E$41 -> 0.026737968 | J10: =$F10/$E$41 -> 0 | K10: =$G10/$E$41 -> 0.021390374 | L10: =$H10/$E$41 -> 0.0053475936 | N10: =+F10/E10 -> 0
B11: 10 | C11: 07 | D11: 30 FT ELECTRICA NARROW | E11: =SUMIFS('CONTROL DE RENTAS'!$V$42:$V$336,'CONTROL DE RENTAS'!$AL$42:$AL$336,$B11,'CONTROL DE RENTAS'!$AM$42:$AM$336,$C11) -> 1 | F11: =SUMIFS('CONTROL DE RENTAS'!$V$42:$V$336,'CONTROL DE RENTAS'!$AL$42:$AL$336,$B11,'CONTROL DE RENTAS'!$AM$42:$AM$336,$C11,'CONTROL DE RENTAS'!$O$42:$O$336,"DENTRO") -> 1 | G11: =SUMIFS('CONTROL DE RENTAS'!$V$42:$V$336,'CONTROL DE RENTAS'!$AL$42:$AL$336,$B11,'CONTROL DE RENTAS'!$AM$42:$AM$336,$C11,'CONTROL DE RENTAS'!$O$42:$O$336,"DISPONIBLE") -> 0 | H11: {=SUM(SUMIFS('CONTROL DE RENTAS'!$V$42:$V$336,'CONTROL DE RENTAS'!$AL$42:$AL$336,$B11,'CONTROL DE RENTAS'!$AM$42:$AM$336,$C11,'CONTROL DE RENTAS'!$O$42:$O$336,'RENTABILIDAD GLOBAL'!$B$33:$B$35))} -> 0 | I11: =$E11/$E$41 -> 0.0053475936 | J11: =$F11/$E$41 -> 0.0053475936 | K11: =$G11/$E$41 -> 0 | L11: =$H11/$E$41 -> 0 | N11: =+F11/E11 -> 1
B12: 10 | C12: 08 | D12: 60 FT COMBUSTION | E12: =SUMIFS('CONTROL DE RENTAS'!$V$42:$V$336,'CONTROL DE RENTAS'!$AL$42:$AL$336,$B12,'CONTROL DE RENTAS'!$AM$42:$AM$336,$C12) -> 8 | F12: =SUMIFS('CONTROL DE RENTAS'!$V$42:$V$336,'CONTROL DE RENTAS'!$AL$42:$AL$336,$B12,'CONTROL DE RENTAS'!$AM$42:$AM$336,$C12,'CONTROL DE RENTAS'!$O$42:$O$336,"DENTRO") -> 7 | G12: =SUMIFS('CONTROL DE RENTAS'!$V$42:$V$336,'CONTROL DE RENTAS'!$AL$42:$AL$336,$B12,'CONTROL DE RENTAS'!$AM$42:$AM$336,$C12,'CONTROL DE RENTAS'!$O$42:$O$336,"DISPONIBLE") -> 0 | H12: {=SUM(SUMIFS('CONTROL DE RENTAS'!$V$42:$V$336,'CONTROL DE RENTAS'!$AL$42:$AL$336,$B12,'CONTROL DE RENTAS'!$AM$42:$AM$336,$C12,'CONTROL DE RENTAS'!$O$42:$O$336,'RENTABILIDAD GLOBAL'!$B$33:$B$35))} -> 1 | I12: =$E12/$E$41 -> 0.042780749 | J12: =$F12/$E$41 -> 0.037433155 | K12: =$G12/$E$41 -> 0 | L12: =$H12/$E$41 -> 0.0053475936 | N12: =+F12/E12 -> 0.875
B13: 10 | C13: 09 | D13: 60 FT ELECTRICA | E13: =SUMIFS('CONTROL DE RENTAS'!$V$42:$V$336,'CONTROL DE RENTAS'!$AL$42:$AL$336,$B13,'CONTROL DE RENTAS'!$AM$42:$AM$336,$C13) -> 0 | F13: =SUMIFS('CONTROL DE RENTAS'!$V$42:$V$336,'CONTROL DE RENTAS'!$AL$42:$AL$336,$B13,'CONTROL DE RENTAS'!$AM$42:$AM$336,$C13,'CONTROL DE RENTAS'!$O$42:$O$336,"DENTRO") -> 0 | G13: =SUMIFS('CONTROL DE RENTAS'!$V$42:$V$336,'CONTROL DE RENTAS'!$AL$42:$AL$336,$B13,'CONTROL DE RENTAS'!$AM$42:$AM$336,$C13,'CONTROL DE RENTAS'!$O$42:$O$336,"DISPONIBLE") -> 0 | H13: {=SUM(SUMIFS('CONTROL DE RENTAS'!$V$42:$V$336,'CONTROL DE RENTAS'!$AL$42:$AL$336,$B13,'CONTROL DE RENTAS'!$AM$42:$AM$336,$C13,'CONTROL DE RENTAS'!$O$42:$O$336,'RENTABILIDAD GLOBAL'!$B$33:$B$35))} -> 0 | I13: =$E13/$E$41 -> 0 | J13: =$F13/$E$41 -> 0 | K13: =$G13/$E$41 -> 0 | L13: =$H13/$E$41 -> 0 | N13: 0
B14: 10 | C14: 10 | D14: 135 FT COMBUSTION CON JIB | E14: =SUMIFS('CONTROL DE RENTAS'!$V$42:$V$336,'CONTROL DE RENTAS'!$AL$42:$AL$336,$B14,'CONTROL DE RENTAS'!$AM$42:$AM$336,$C14) -> 1 | F14: =SUMIFS('CONTROL DE RENTAS'!$V$42:$V$336,'CONTROL DE RENTAS'!$AL$42:$AL$336,$B14,'CONTROL DE RENTAS'!$AM$42:$AM$336,$C14,'CONTROL DE RENTAS'!$O$42:$O$336,"DENTRO") -> 0 | G14: =SUMIFS('CONTROL DE RENTAS'!$V$42:$V$336,'CONTROL DE RENTAS'!$AL$42:$AL$336,$B14,'CONTROL DE RENTAS'!$AM$42:$AM$336,$C14,'CONTROL DE RENTAS'!$O$42:$O$336,"DISPONIBLE") -> 0 | H14: {=SUM(SUMIFS('CONTROL DE RENTAS'!$V$42:$V$336,'CONTROL DE RENTAS'!$AL$42:$AL$336,$B14,'CONTROL DE RENTAS'!$AM$42:$AM$336,$C14,'CONTROL DE RENTAS'!$O$42:$O$336,'RENTABILIDAD GLOBAL'!$B$33:$B$35))} -> 1 | I14: =$E14/$E$41 -> 0.0053475936 | J14: =$F14/$E$41 -> 0 | K14: =$G14/$E$41 -> 0 | L14: =$H14/$E$41 -> 0.0053475936 | N14: 0
B15: 20 | C15: PLATAFORMAS TELESCOPICAS | G15: =SUMIFS('CONTROL DE RENTAS'!$V$43:$V$336,'CONTROL DE RENTAS'!$AL$43:$AL$336,$B15,'CONTROL DE RENTAS'!$AM$43:$AM$336,$C15,'CONTROL DE RENTAS'!$O$43:$O$336,"DISPONIBLE") -> 0 | J15: =SUM(F16:F17)/$E$41 -> 0.026737968
B16: 20 | C16: 01 | D16: 60 FT COMBUSTION | E16: =SUMIFS('CONTROL DE RENTAS'!$V$42:$V$336,'CONTROL DE RENTAS'!$AL$42:$AL$336,$B16,'CONTROL DE RENTAS'!$AM$42:$AM$336,$C16) -> 5 | F16: =SUMIFS('CONTROL DE RENTAS'!$V$42:$V$336,'CONTROL DE RENTAS'!$AL$42:$AL$336,$B16,'CONTROL DE RENTAS'!$AM$42:$AM$336,$C16,'CONTROL DE RENTAS'!$O$42:$O$336,"DENTRO") -> 3 | G16: =SUMIFS('CONTROL DE RENTAS'!$V$42:$V$336,'CONTROL DE RENTAS'!$AL$42:$AL$336,$B16,'CONTROL DE RENTAS'!$AM$42:$AM$336,$C16,'CONTROL DE RENTAS'!$O$42:$O$336,"DISPONIBLE") -> 0 | H16: {=SUM(SUMIFS('CONTROL DE RENTAS'!$V$42:$V$336,'CONTROL DE RENTAS'!$AL$42:$AL$336,$B16,'CONTROL DE RENTAS'!$AM$42:$AM$336,$C16,'CONTROL DE RENTAS'!$O$42:$O$336,'RENTABILIDAD GLOBAL'!$B$33:$B$35))} -> 2 | I16: =$E16/$E$41 -> 0.026737968 | J16: =$F16/$E$41 -> 0.016042781 | K16: =$G16/$E$41 -> 0 | L16: =$H16/$E$41 -> 0.010695187 | N16: =+F16/E16 -> 0.6
B17: 20 | C17: 02 | D17: 80 FT COMBUSTION | E17: =SUMIFS('CONTROL DE RENTAS'!$V$42:$V$336,'CONTROL DE RENTAS'!$AL$42:$AL$336,$B17,'CONTROL DE RENTAS'!$AM$42:$AM$336,$C17) -> 5 | F17: =SUMIFS('CONTROL DE RENTAS'!$V$42:$V$336,'CONTROL DE RENTAS'!$AL$42:$AL$336,$B17,'CONTROL DE RENTAS'!$AM$42:$AM$336,$C17,'CONTROL DE RENTAS'!$O$42:$O$336,"DENTRO") -> 2 | G17: =SUMIFS('CONTROL DE RENTAS'!$V$42:$V$336,'CONTROL DE RENTAS'!$AL$42:$AL$336,$B17,'CONTROL DE RENTAS'!$AM$42:$AM$336,$C17,'CONTROL DE RENTAS'!$O$42:$O$336,"DISPONIBLE") -> 0 | H17: {=SUM(SUMIFS('CONTROL DE RENTAS'!$V$42:$V$336,'CONTROL DE RENTAS'!$AL$42:$AL$336,$B17,'CONTROL DE RENTAS'!$AM$42:$AM$336,$C17,'CONTROL DE RENTAS'!$O$42:$O$336,'RENTABILIDAD GLOBAL'!$B$33:$B$35))} -> 3 | I17: =$E17/$E$41 -> 0.026737968 | J17: =$F17/$E$41 -> 0.010695187 | K17: =$G17/$E$41 -> 0 | L17: =$H17/$E$41 -> 0.016042781 | N17: =+F17/E17 -> 0.4
B18: 30 | C18: PLATAFORMAS TIPO TIJERA | G18: =SUMIFS('CONTROL DE RENTAS'!$V$43:$V$336,'CONTROL DE RENTAS'!$AL$43:$AL$336,$B18,'CONTROL DE RENTAS'!$AM$43:$AM$336,$C18,'CONTROL DE RENTAS'!$O$43:$O$336,"DISPONIBLE") -> 0 | J18: =SUM(F19:F23)/$E$41 -> 0.07486631
B19: 30 | C19: 01 | D19: 19 FT ELECTRICA | E19: =SUMIFS('CONTROL DE RENTAS'!$V$42:$V$336,'CONTROL DE RENTAS'!$AL$42:$AL$336,$B19,'CONTROL DE RENTAS'!$AM$42:$AM$336,$C19) -> 7 | F19: =SUMIFS('CONTROL DE RENTAS'!$V$42:$V$336,'CONTROL DE RENTAS'!$AL$42:$AL$336,$B19,'CONTROL DE RENTAS'!$AM$42:$AM$336,$C19,'CONTROL DE RENTAS'!$O$42:$O$336,"DENTRO") -> 7 | G19: =SUMIFS('CONTROL DE RENTAS'!$V$42:$V$336,'CONTROL DE RENTAS'!$AL$42:$AL$336,$B19,'CONTROL DE RENTAS'!$AM$42:$AM$336,$C19,'CONTROL DE RENTAS'!$O$42:$O$336,"DISPONIBLE") -> 0 | H19: {=SUM(SUMIFS('CONTROL DE RENTAS'!$V$42:$V$336,'CONTROL DE RENTAS'!$AL$42:$AL$336,$B19,'CONTROL DE RENTAS'!$AM$42:$AM$336,$C19,'CONTROL DE RENTAS'!$O$42:$O$336,'RENTABILIDAD GLOBAL'!$B$33:$B$35))} -> 0 | I19: =$E19/$E$41 -> 0.037433155 | J19: =$F19/$E$41 -> 0.037433155 | K19: =$G19/$E$41 -> 0 | L19: =$H19/$E$41 -> 0 | N19: =+F19/E19 -> 1
B20: 30 | C20: 02 | D20: 26 FT ELECTRICA | E20: =SUMIFS('CONTROL DE RENTAS'!$V$42:$V$336,'CONTROL DE RENTAS'!$AL$42:$AL$336,$B20,'CONTROL DE RENTAS'!$AM$42:$AM$336,$C20) -> 1 | F20: =SUMIFS('CONTROL DE RENTAS'!$V$42:$V$336,'CONTROL DE RENTAS'!$AL$42:$AL$336,$B20,'CONTROL DE RENTAS'!$AM$42:$AM$336,$C20,'CONTROL DE RENTAS'!$O$42:$O$336,"DENTRO") -> 1 | G20: =SUMIFS('CONTROL DE RENTAS'!$V$42:$V$336,'CONTROL DE RENTAS'!$AL$42:$AL$336,$B20,'CONTROL DE RENTAS'!$AM$42:$AM$336,$C20,'CONTROL DE RENTAS'!$O$42:$O$336,"DISPONIBLE") -> 0 | H20: {=SUM(SUMIFS('CONTROL DE RENTAS'!$V$42:$V$336,'CONTROL DE RENTAS'!$AL$42:$AL$336,$B20,'CONTROL DE RENTAS'!$AM$42:$AM$336,$C20,'CONTROL DE RENTAS'!$O$42:$O$336,'RENTABILIDAD GLOBAL'!$B$33:$B$35))} -> 0 | I20: =$E20/$E$41 -> 0.0053475936 | J20: =$F20/$E$41 -> 0.0053475936 | K20: =$G20/$E$41 -> 0 | L20: =$H20/$E$41 -> 0 | N20: =+F20/E20 -> 1
B21: 30 | C21: 03 | D21: 32 FT ELECTRICA | E21: =SUMIFS('CONTROL DE RENTAS'!$V$42:$V$336,'CONTROL DE RENTAS'!$AL$42:$AL$336,$B21,'CONTROL DE RENTAS'!$AM$42:$AM$336,$C21) -> 4 | F21: =SUMIFS('CONTROL DE RENTAS'!$V$42:$V$336,'CONTROL DE RENTAS'!$AL$42:$AL$336,$B21,'CONTROL DE RENTAS'!$AM$42:$AM$336,$C21,'CONTROL DE RENTAS'!$O$42:$O$336,"DENTRO") -> 0 | G21: =SUMIFS('CONTROL DE RENTAS'!$V$42:$V$336,'CONTROL DE RENTAS'!$AL$42:$AL$336,$B21,'CONTROL DE RENTAS'!$AM$42:$AM$336,$C21,'CONTROL DE RENTAS'!$O$42:$O$336,"DISPONIBLE") -> 2 | H21: {=SUM(SUMIFS('CONTROL DE RENTAS'!$V$42:$V$336,'CONTROL DE RENTAS'!$AL$42:$AL$336,$B21,'CONTROL DE RENTAS'!$AM$42:$AM$336,$C21,'CONTROL DE RENTAS'!$O$42:$O$336,'RENTABILIDAD GLOBAL'!$B$33:$B$35))} -> 2 | I21: =$E21/$E$41 -> 0.021390374 | J21: =$F21/$E$41 -> 0 | K21: =$G21/$E$41 -> 0.010695187 | L21: =$H21/$E$41 -> 0.010695187 | N21: =+F21/E21 -> 0
B22: 30 | C22: 04 | D22: 40 FT ELECTRICA | E22: =SUMIFS('CONTROL DE RENTAS'!$V$42:$V$336,'CONTROL DE RENTAS'!$AL$42:$AL$336,$B22,'CONTROL DE RENTAS'!$AM$42:$AM$336,$C22) -> 7 | F22: =SUMIFS('CONTROL DE RENTAS'!$V$42:$V$336,'CONTROL DE RENTAS'!$AL$42:$AL$336,$B22,'CONTROL DE RENTAS'!$AM$42:$AM$336,$C22,'CONTROL DE RENTAS'!$O$42:$O$336,"DENTRO") -> 4 | G22: =SUMIFS('CONTROL DE RENTAS'!$V$42:$V$336,'CONTROL DE RENTAS'!$AL$42:$AL$336,$B22,'CONTROL DE RENTAS'!$AM$42:$AM$336,$C22,'CONTROL DE RENTAS'!$O$42:$O$336,"DISPONIBLE") -> 3 | H22: {=SUM(SUMIFS('CONTROL DE RENTAS'!$V$42:$V$336,'CONTROL DE RENTAS'!$AL$42:$AL$336,$B22,'CONTROL DE RENTAS'!$AM$42:$AM$336,$C22,'CONTROL DE RENTAS'!$O$42:$O$336,'RENTABILIDAD GLOBAL'!$B$33:$B$35))} -> 0 | I22: =$E22/$E$41 -> 0.037433155 | J22: =$F22/$E$41 -> 0.021390374 | K22: =$G22/$E$41 -> 0.016042781 | L22: =$H22/$E$41 -> 0 | N22: =+F22/E22 -> 0.57142857
B23: 30 | C23: 05 | D23: 53 FT COMBUSTION | E23: =SUMIFS('CONTROL DE RENTAS'!$V$42:$V$336,'CONTROL DE RENTAS'!$AL$42:$AL$336,$B23,'CONTROL DE RENTAS'!$AM$42:$AM$336,$C23) -> 3 | F23: =SUMIFS('CONTROL DE RENTAS'!$V$42:$V$336,'CONTROL DE RENTAS'!$AL$42:$AL$336,$B23,'CONTROL DE RENTAS'!$AM$42:$AM$336,$C23,'CONTROL DE RENTAS'!$O$42:$O$336,"DENTRO") -> 2 | G23: =SUMIFS('CONTROL DE RENTAS'!$V$42:$V$336,'CONTROL DE RENTAS'!$AL$42:$AL$336,$B23,'CONTROL DE RENTAS'!$AM$42:$AM$336,$C23,'CONTROL DE RENTAS'!$O$42:$O$336,"DISPONIBLE") -> 1 | H23: {=SUM(SUMIFS('CONTROL DE RENTAS'!$V$42:$V$336,'CONTROL DE RENTAS'!$AL$42:$AL$336,$B23,'CONTROL DE RENTAS'!$AM$42:$AM$336,$C23,'CONTROL DE RENTAS'!$O$42:$O$336,'RENTABILIDAD GLOBAL'!$B$33:$B$35))} -> 0 | I23: =$E23/$E$41 -> 0.016042781 | J23: =$F23/$E$41 -> 0.010695187 | K23: =$G23/$E$41 -> 0.0053475936 | L23: =$H23/$E$41 -> 0 | N23: =+F23/E23 -> 0.66666667
B24: 40 | C24: COMPRESORES | G24: =SUMIFS('CONTROL DE RENTAS'!$V$43:$V$336,'CONTROL DE RENTAS'!$AL$43:$AL$336,$B24,'CONTROL DE RENTAS'!$AM$43:$AM$336,$C24,'CONTROL DE RENTAS'!$O$43:$O$336,"DISPONIBLE") -> 0 | J24: =SUM(F25:F26)/$E$41 -> 0.010695187
B25: 40 | C25: 01 | D25: COMPRESOR 185CFM | E25: =SUMIFS('CONTROL DE RENTAS'!$V$42:$V$336,'CONTROL DE RENTAS'!$AL$42:$AL$336,$B25,'CONTROL DE RENTAS'!$AM$42:$AM$336,$C25) -> 7 | F25: =SUMIFS('CONTROL DE RENTAS'!$V$42:$V$336,'CONTROL DE RENTAS'!$AL$42:$AL$336,$B25,'CONTROL DE RENTAS'!$AM$42:$AM$336,$C25,'CONTROL DE RENTAS'!$O$42:$O$336,"DENTRO") -> 1 | G25: =SUMIFS('CONTROL DE RENTAS'!$V$42:$V$336,'CONTROL DE RENTAS'!$AL$42:$AL$336,$B25,'CONTROL DE RENTAS'!$AM$42:$AM$336,$C25,'CONTROL DE RENTAS'!$O$42:$O$336,"DISPONIBLE") -> 6 | H25: {=SUM(SUMIFS('CONTROL DE RENTAS'!$V$42:$V$336,'CONTROL DE RENTAS'!$AL$42:$AL$336,$B25,'CONTROL DE RENTAS'!$AM$42:$AM$336,$C25,'CONTROL DE RENTAS'!$O$42:$O$336,'RENTABILIDAD GLOBAL'!$B$33:$B$35))} -> 0 | I25: =$E25/$E$41 -> 0.037433155 | J25: =$F25/$E$41 -> 0.0053475936 | K25: =$G25/$E$41 -> 0.032085561 | L25: =$H25/$E$41 -> 0 | N25: =+F25/E25 -> 0.14285714
B26: 40 | C26: 02 | D26: COMPRESOR 375CFM | E26: =SUMIFS('CONTROL DE RENTAS'!$V$42:$V$336,'CONTROL DE RENTAS'!$AL$42:$AL$336,$B26,'CONTROL DE RENTAS'!$AM$42:$AM$336,$C26) -> 4 | F26: =SUMIFS('CONTROL DE RENTAS'!$V$42:$V$336,'CONTROL DE RENTAS'!$AL$42:$AL$336,$B26,'CONTROL DE RENTAS'!$AM$42:$AM$336,$C26,'CONTROL DE RENTAS'!$O$42:$O$336,"DENTRO") -> 1 | G26: =SUMIFS('CONTROL DE RENTAS'!$V$42:$V$336,'CONTROL DE RENTAS'!$AL$42:$AL$336,$B26,'CONTROL DE RENTAS'!$AM$42:$AM$336,$C26,'CONTROL DE RENTAS'!$O$42:$O$336,"DISPONIBLE") -> 1 | H26: {=SUM(SUMIFS('CONTROL DE RENTAS'!$V$42:$V$336,'CONTROL DE RENTAS'!$AL$42:$AL$336,$B26,'CONTROL DE RENTAS'!$AM$42:$AM$336,$C26,'CONTROL DE RENTAS'!$O$42:$O$336,'RENTABILIDAD GLOBAL'!$B$33:$B$35))} -> 2 | I26: =$E26/$E$41 -> 0.021390374 | J26: =$F26/$E$41 -> 0.0053475936 | K26: =$G26/$E$41 -> 0.0053475936 | L26: =$H26/$E$41 -> 0.010695187 | N26: =+F26/E26 -> 0.25
